File: old/analysis_20190400_old/Specimen_RawData_7.csv
End date,"11/4/2016"
Specimen label,"63G_"
Maximum Load,"2.39940",N

Time,Extension,Load
(s),(mm),(N)
"0.00000","0.29327","-0.00271"
"0.42000","0.32854","-0.00198"
"0.84000","0.36352","-0.00134"
"1.26000","0.39850","-0.00095"
"1.68000","0.43347","-0.00047"
"2.10000","0.46839","0.00054"
"2.52000","0.50343","-0.00076"
"2.94000","0.53846","-0.00018"
"3.36000","0.57344","0.00065"
"3.78000","0.60842","0.00067"
"4.20000","0.64340","0.00088"
"4.62000","0.67843","0.00129"
"5.04000","0.71341","0.00155"
"5.46000","0.74845","0.00172"
"5.88000","0.78336","0.00221"
"6.30000","0.81846","0.00171"
"6.72000","0.85344","0.00190"
"7.14000","0.88847","0.00215"
"7.56000","0.92339","0.00287"
"7.98000","0.95837","0.00221"
"8.40000","0.99340","0.00300"
"8.82000","1.02838","0.00266"
"9.24000","1.06342","0.00302"
"9.66000","1.09839","0.00288"
"10.08000","1.13337","0.00336"
"10.50000","1.16841","0.00354"
"10.92000","1.20344","0.00398"
"11.34000","1.23842","0.00370"
"11.76000","1.27346","0.00356"
"12.18000","1.30849","0.00428"
"12.60000","1.34347","0.00441"
"13.02000","1.37845","0.00451"
"13.44000","1.41336","0.00509"
"13.86000","1.44840","0.00524"
"14.28000","1.48344","0.00530"
"14.70000","1.51836","0.00619"
"15.12000","1.55345","0.00635"
"15.54000","1.58837","0.00680"
"15.96000","1.62341","0.00689"
"16.38000","1.65844","0.00687"
"16.80000","1.69342","0.00715"
"17.22000","1.72840","0.00700"
"17.64000","1.76343","0.00727"
"18.06000","1.79847","0.00722"
"18.48000","1.83345","0.00770"
"18.90000","1.86842","0.00836"
"19.32000","1.90334","0.00882"
"19.74000","1.93838","0.00974"
"20.16000","1.97341","0.00915"
"20.58000","2.00845","0.00959"
"21.00000","2.04337","0.00993"
"21.42000","2.07840","0.00894"
"21.84000","2.11344","0.00986"
"22.26000","2.14842","0.01090"
"22.68000","2.18339","0.01084"
"23.10000","2.21837","0.01119"
"23.52000","2.25341","0.01161"
"23.94000","2.28844","0.01270"
"24.36000","2.32348","0.01233"
"24.78000","2.35846","0.01328"
"25.20000","2.39337","0.01350"
"25.62000","2.42841","0.01392"
"26.04000","2.46339","0.01446"
"26.46000","2.49843","0.01482"
"26.88000","2.53340","0.01499"
"27.30000","2.56838","0.01561"
"27.72000","2.60348","0.01596"
"28.14000","2.63845","0.01536"
"28.56000","2.67343","0.01576"
"28.98000","2.70841","0.01648"
"29.40000","2.74344","0.01664"
"29.82000","2.77842","0.01738"
"30.24000","2.81346","0.01799"
"30.66000","2.84837","0.01770"
"31.08000","2.88341","0.01782"
"31.50000","2.91845","0.01893"
"31.92000","2.95342","0.01878"
"32.34000","2.98840","0.01965"
"32.76000","3.02338","0.01983"
"33.18000","3.05835","0.02008"
"33.60000","3.09345","0.02021"
"34.02000","3.12843","0.02040"
"34.44000","3.16340","0.02102"
"34.86000","3.19838","0.02140"
"35.28000","3.23342","0.02136"
"35.70000","3.26845","0.02145"
"36.12000","3.30343","0.02166"
"36.54000","3.33841","0.02176"
"36.96000","3.37339","0.02188"
"37.38000","3.40842","0.02286"
"37.80000","3.44346","0.02283"
"38.22000","3.47838","0.02297"
"38.64000","3.51335","0.02329"
"39.06000","3.54839","0.02401"
"39.48000","3.58343","0.02418"
"39.90000","3.61840","0.02373"
"40.32000","3.65338","0.02460"
"40.74000","3.68842","0.02489"
"41.16000","3.72345","0.02529"
"41.58000","3.75843","0.02590"
"42.00000","3.79347","0.02623"
"42.42000","3.82838","0.02639"
"42.84000","3.86342","0.02691"
"43.26000","3.89846","0.02715"
"43.68000","3.93343","0.02746"
"44.10000","3.96835","0.02741"
"44.52000","4.00339","0.02802"
"44.94000","4.03842","0.02856"
"45.36000","4.07346","0.02873"
"45.78000","4.10838","0.02916"
"46.20000","4.14335","0.02953"
"46.62000","4.17845","0.02883"
"47.04000","4.21343","0.02998"
"47.46000","4.24840","0.03060"
"47.88000","4.28338","0.03146"
"48.30000","4.31842","0.03222"
"48.72000","4.35340","0.03232"
"49.14000","4.38843","0.03391"
"49.56000","4.42341","0.03473"
"49.98000","4.45833","0.03585"
"50.40000","4.49336","0.03615"
"50.82000","4.52846","0.03675"
"51.24000","4.56344","0.03828"
"51.66000","4.59841","0.03933"
"52.08000","4.63339","0.04031"
"52.50000","4.66849","0.04129"
"52.92000","4.70346","0.04301"
"53.34000","4.73844","0.04474"
"53.76000","4.77336","0.04553"
"54.18000","4.80839","0.04695"
"54.60000","4.84343","0.04773"
"55.02000","4.87841","0.04801"
"55.44000","4.91338","0.05106"
"55.86000","4.94836","0.05196"
"56.28000","4.98346","0.05327"
"56.70000","5.01843","0.05341"
"57.12000","5.05341","0.05481"
"57.54000","5.08833","0.05650"
"57.96000","5.12343","0.05723"
"58.38000","5.15846","0.05855"
"58.80000","5.19344","0.05958"
"59.22000","5.22842","0.06020"
"59.64000","5.26339","0.06181"
"60.06000","5.29843","0.06252"
"60.48000","5.33341","0.06331"
"60.90000","5.36838","0.06538"
"61.32000","5.40330","0.06620"
"61.74000","5.43840","0.06636"
"62.16000","5.47343","0.06835"
"62.58000","5.50847","0.06921"
"63.00000","5.54339","0.07085"
"63.42000","5.57836","0.07080"
"63.84000","5.61346","0.07257"
"64.26000","5.64844","0.07291"
"64.68000","5.68341","0.07307"
"65.10000","5.71839","0.07434"
"65.52000","5.75343","0.07478"
"65.94000","5.78840","0.07505"
"66.36000","5.82344","0.07611"
"66.78000","5.85842","0.07616"
"67.20000","5.89333","0.07679"
"67.62000","5.92843","0.07689"
"68.04000","5.96341","0.07752"
"68.46000","5.99844","0.07772"
"68.88000","6.03336","0.07798"
"69.30000","6.06840","0.07831"
"69.72000","6.10349","0.07858"
"70.14000","6.13841","0.07878"
"70.56000","6.17345","0.07969"
"70.98000","6.20843","0.08051"
"71.40000","6.24340","0.08060"
"71.82000","6.27844","0.08194"
"72.24000","6.31348","0.08325"
"72.66000","6.34833","0.08477"
"73.08000","6.38343","0.08569"
"73.50000","6.41841","0.08696"
"73.92000","6.45344","0.08839"
"74.34000","6.48842","0.08931"
"74.76000","6.52340","0.09054"
"75.18000","6.55843","0.09221"
"75.60000","6.59341","0.09386"
"76.02000","6.62845","0.09477"
"76.44000","6.66342","0.09675"
"76.86000","6.69834","0.09822"
"77.28000","6.73344","0.09869"
"77.70000","6.76841","0.10070"
"78.12000","6.80345","0.10219"
"78.54000","6.83837","0.10404"
"78.96000","6.87340","0.10619"
"79.38000","6.90844","0.10874"
"79.80000","6.94348","0.11168"
"80.22000","6.97840","0.11371"
"80.64000","7.01337","0.11581"
"81.06000","7.04847","0.11814"
"81.48000","7.08351","0.12028"
"81.90000","7.11842","0.12267"
"82.32000","7.15334","0.12532"
"82.74000","7.18844","0.12827"
"83.16000","7.22341","0.13062"
"83.58000","7.25845","0.13305"
"84.00000","7.29343","0.13515"
"84.42000","7.32834","0.13658"
"84.84000","7.36338","0.13789"
"85.26000","7.39842","0.13899"
"85.68000","7.43345","0.13909"
"86.10000","7.46843","0.13969"
"86.52000","7.50341","0.13986"
"86.94000","7.53844","0.14021"
"87.36000","7.57342","0.14109"
"87.78000","7.60846","0.14224"
"88.20000","7.64337","0.14425"
"88.62000","7.67835","0.14622"
"89.04000","7.71345","0.14986"
"89.46000","7.74842","0.15242"
"89.88000","7.78334","0.15470"
"90.30000","7.81838","0.15719"
"90.72000","7.85347","0.15937"
"91.14000","7.88839","0.16219"
"91.56000","7.92343","0.16460"
"91.98000","7.95841","0.16727"
"92.40000","7.99344","0.16957"
"92.82000","8.02842","0.17151"
"93.24000","8.06346","0.17302"
"93.66000","8.09843","0.17511"
"94.08000","8.13335","0.17696"
"94.50000","8.16845","0.17842"
"94.92000","8.20342","0.18058"
"95.34000","8.23846","0.18285"
"95.76000","8.27332","0.18541"
"96.18000","8.30841","0.18771"
"96.60000","8.34345","0.19026"
"97.02000","8.37843","0.19266"
"97.44000","8.41340","0.18291"
"97.86000","8.44844","0.18527"
"98.28000","8.48342","0.18837"
"98.70000","8.51845","0.19136"
"99.12000","8.55343","0.19500"
"99.54000","8.58835","0.19905"
"99.96000","8.62338","0.20214"
"100.38000","8.65842","0.20643"
"100.80000","8.69340","0.21021"
"101.22000","8.72837","0.21429"
"101.64000","8.76335","0.21932"
"102.06000","8.79839","0.22354"
"102.48000","8.83343","0.22944"
"102.90000","8.86846","0.23360"
"103.32000","8.90344","0.23679"
"103.74000","8.93836","0.23953"
"104.16000","8.97345","0.24313"
"104.58000","9.00843","0.24772"
"105.00000","9.04347","0.25384"
"105.42000","9.07838","0.25960"
"105.84000","9.11336","0.26481"
"106.26000","9.14846","0.26533"
"106.68000","9.18343","0.26917"
"107.10000","9.21835","0.27349"
"107.52000","9.25345","0.27795"
"107.94000","9.28842","0.28131"
"108.36000","9.32340","0.28457"
"108.78000","9.35844","0.28654"
"109.20000","9.39341","0.28753"
"109.62000","9.42845","0.28794"
"110.04000","9.46343","0.28814"
"110.46000","9.49846","0.28835"
"110.88000","9.53344","0.28890"
"111.30000","9.56836","0.29000"
"111.72000","9.60345","0.29186"
"112.14000","9.63843","0.29469"
"112.56000","9.67341","0.29933"
"112.98000","9.70833","0.30384"
"113.40000","9.74336","0.30926"
"113.82000","9.77846","0.31478"
"114.24000","9.81344","0.32202"
"114.66000","9.84835","0.32977"
"115.08000","9.88339","0.33649"
"115.50000","9.91843","0.33964"
"115.92000","9.95346","0.34236"
"116.34000","9.98844","0.34702"
"116.76000","10.02342","0.35361"
"117.18000","10.05839","0.36348"
"117.60000","10.09337","0.37171"
"118.02000","10.12841","0.37859"
"118.44000","10.16338","0.38368"
"118.86000","10.19836","0.38800"
"119.28000","10.23340","0.39171"
"119.70000","10.26843","0.39494"
"120.12000","10.30341","0.39920"
"120.54000","10.33839","0.40279"
"120.96000","10.37336","0.40532"
"121.38000","10.40846","0.40814"
"121.80000","10.44344","0.41198"
"122.22000","10.47841","0.41659"
"122.64000","10.51339","0.42255"
"123.06000","10.54837","0.42786"
"123.48000","10.58346","0.43554"
"123.90000","10.61844","0.43985"
"124.32000","10.65336","0.44221"
"124.74000","10.68839","0.44497"
"125.16000","10.72337","0.45095"
"125.58000","10.75841","0.45847"
"126.00000","10.79339","0.46391"
"126.42000","10.82836","0.47068"
"126.84000","10.86340","0.47871"
"127.26000","10.89838","0.48478"
"127.68000","10.93347","0.48803"
"128.10001","10.96845","0.49041"
"128.52000","11.00337","0.49331"
"128.94000","11.03846","0.49826"
"129.36000","11.07338","0.50600"
"129.78000","11.10842","0.51553"
"130.20000","11.14333","0.52321"
"130.62000","11.17843","0.52970"
"131.03999","11.21347","0.53806"
"131.46001","11.24844","0.54652"
"131.88000","11.28336","0.55178"
"132.30000","11.31840","0.55729"
"132.72000","11.35343","0.56685"
"133.14000","11.38847","0.57592"
"133.56000","11.42345","0.58311"
"133.98000","11.45842","0.58880"
"134.39999","11.49340","0.59264"
"134.82001","11.52844","0.59573"
"135.24001","11.56341","0.59902"
"135.66000","11.59839","0.60422"
"136.08000","11.63331","0.61069"
"136.50000","11.66841","0.61776"
"136.92000","11.70338","0.62558"
"137.34000","11.73842","0.63728"
"137.75999","11.77340","0.64782"
"138.17999","11.80837","0.65489"
"138.60001","11.84347","0.66595"
"139.02000","11.87845","0.67709"
"139.44000","11.91348","0.68500"
"139.86000","11.94840","0.69249"
"140.28000","11.98338","0.69771"
"140.70000","12.01841","0.70184"
"141.12000","12.05339","0.70442"
"141.53999","12.08837","0.70686"
"141.96001","12.12334","0.71112"
"142.38000","12.15844","0.71947"
"142.80000","12.19342","0.72899"
"143.22000","12.22839","0.73881"
"143.64000","12.26337","0.74830"
"144.06000","12.29841","0.75352"
"144.48000","12.33338","0.76049"
"144.89999","12.36848","0.77083"
"145.32001","12.40346","0.77998"
"145.74001","12.43838","0.79113"
"146.16000","12.47341","0.80075"
"146.58000","12.50839","0.80779"
"147.00000","12.54342","0.81449"
"147.42000","12.57834","0.82029"
"147.84000","12.61344","0.82702"
"148.25999","12.64848","0.83615"
"148.67999","12.68345","0.84734"
"149.10001","12.71837","0.85480"
"149.52000","12.75335","0.86323"
"149.94000","12.78844","0.87725"
"150.36000","12.82348","0.88842"
"150.78000","12.85840","0.90061"
"151.20000","12.89337","0.90696"
"151.62000","12.92841","0.90860"
"152.03999","12.96345","0.90959"
"152.46001","12.99842","0.91181"
"152.88000","13.03340","0.90899"
"153.30000","13.06838","0.90858"
"153.72000","13.10335","0.91123"
"154.14000","13.13839","0.92571"
"154.56000","13.17343","0.94207"
"154.98000","13.20840","0.95981"
"155.39999","13.24332","0.96916"
"155.82001","13.27842","0.98125"
"156.24001","13.31346","0.99061"
"156.66000","13.34843","1.00013"
"157.08000","13.38335","1.00697"
"157.50000","13.41838","1.01404"
"157.92000","13.45342","1.02369"
"158.34000","13.48846","1.03648"
"158.75999","13.52338","1.05019"
"159.17999","13.55841","1.05831"
"159.60001","13.59345","1.06329"
"160.02000","13.62843","1.07877"
"160.44000","13.66340","1.09231"
"160.86000","13.69838","1.10548"
"161.28000","13.73342","1.11274"
"161.70000","13.76839","1.11723"
"162.12000","13.80349","1.12095"
"162.53999","13.83847","1.12631"
"162.96001","13.87338","1.13738"
"163.38000","13.90842","1.15582"
"163.80000","13.94340","1.16822"
"164.22000","13.97843","1.18256"
"164.64000","14.01335","1.19728"
"165.06000","14.04839","1.20764"
"165.48000","14.08348","1.21551"
"165.89999","14.11840","1.22007"
"166.32001","14.15338","1.22606"
"166.74001","14.18835","1.23804"
"167.16000","14.22345","1.25277"
"167.58000","14.25849","1.26694"
"168.00000","14.29341","1.27213"
"168.42000","14.32832","1.28368"
"168.84000","14.36342","1.29756"
"169.25999","14.39840","1.31227"
"169.67999","14.43343","1.32237"
"170.10001","14.46841","1.32922"
"170.52000","14.50333","1.33642"
"170.94000","14.53842","1.35000"
"171.36000","14.57346","1.36556"
"171.78000","14.60844","1.37340"
"172.20000","14.64341","1.38468"
"172.62000","14.67839","1.39979"
"173.03999","14.71349","1.40929"
"173.46001","14.74846","1.41618"
"173.88000","14.78344","1.42208"
"174.30000","14.81836","1.43124"
"174.72000","14.85339","1.44913"
"175.14000","14.88849","1.47198"
"175.56000","14.92341","1.47742"
"175.98000","14.95839","1.34861"
"176.39999","14.99342","1.32940"
"176.82001","15.02840","1.33195"
"177.24001","15.06338","1.33882"
"177.66000","15.09847","1.35174"
"178.08000","15.13339","1.36767"
"178.50000","15.16842","1.37537"
"178.92000","15.20340","1.39162"
"179.34000","15.23844","1.40591"
"179.75999","15.27342","1.41398"
"180.17999","15.30839","1.42055"
"180.60001","15.34343","1.42809"
"181.02000","15.37841","1.44479"
"181.44000","15.41338","1.46856"
"181.86000","15.44836","1.22773"
"182.28000","15.48340","1.22877"
"182.70000","15.51843","1.23553"
"183.12000","15.55341","1.20986"
"183.53999","15.58839","1.21909"
"183.96001","15.62336","1.22504"
"184.38000","15.65840","1.24250"
"184.80000","15.69350","1.26351"
"185.22000","15.72841","1.27280"
"185.64000","15.76339","1.29147"
"186.06000","15.79843","1.30968"
"186.48000","15.83340","1.32392"
"186.89999","15.86838","1.33096"
"187.32001","15.90342","1.34536"
"187.74001","15.93839","1.36395"
"188.16000","15.97337","1.37530"
"188.58000","16.00841","1.39110"
"189.00000","16.04345","1.40795"
"189.42000","16.07842","1.41548"
"189.84000","16.11340","1.42317"
"190.25999","16.14849","1.43453"
"190.67999","16.18347","1.46162"
"191.10001","16.21845","1.47813"
"191.52000","16.25336","1.48948"
"191.94000","16.28840","1.50802"
"192.36000","16.32344","1.52024"
"192.78000","16.35842","1.52563"
"193.20000","16.39339","1.52864"
"193.62000","16.42837","1.53721"
"194.03999","16.46341","1.55324"
"194.46001","16.49838","1.57201"
"194.88000","16.53342","1.57941"
"195.30000","16.56840","1.60212"
"195.72000","16.60337","1.61732"
"196.14000","16.63841","1.62606"
"196.56000","16.67351","1.63605"
"196.98000","16.70842","1.64557"
"197.39999","16.74334","1.65763"
"197.82001","16.77844","1.67366"
"198.24001","16.81341","1.67894"
"198.66000","16.84839","1.68856"
"199.08000","16.88331","1.70177"
"199.50000","16.91840","1.71774"
"199.92000","16.95344","1.72952"
"200.34000","16.98842","1.73636"
"200.75999","17.02340","1.73973"
"201.17999","17.05837","1.74281"
"201.60001","17.09347","1.74275"
"202.02000","17.12844","1.74471"
"202.44000","17.16342","1.75610"
"202.86000","17.19840","1.76969"
"203.28000","17.23338","1.78796"
"203.70000","17.26841","1.80153"
"204.12000","17.30339","1.81881"
"204.53999","17.33843","1.82584"
"204.96001","17.37334","1.82695"
"205.38000","17.40838","1.82965"
"205.80000","17.44342","1.84194"
"206.22000","17.47845","1.86367"
"206.64000","17.51337","1.88722"
"207.06000","17.54835","1.89614"
"207.48000","17.58350","1.91756"
"207.89999","17.61848","1.93757"
"208.32001","17.65340","1.94759"
"208.74001","17.68838","1.95194"
"209.16000","17.72341","1.95979"
"209.58000","17.75845","1.97135"
"210.00000","17.79342","1.98210"
"210.42000","17.82834","2.00076"
"210.84000","17.86332","2.02390"
"211.25999","17.89841","2.03794"
"211.67999","17.93339","2.04026"
"212.10001","17.96843","2.05003"
"212.52000","18.00341","2.06945"
"212.94000","18.03838","2.09283"
"213.36000","18.07342","2.10085"
"213.78000","18.10846","2.11041"
"214.20000","18.14343","2.11989"
"214.62000","18.17841","2.12980"
"215.03999","18.21345","2.13790"
"215.46001","18.24842","1.99739"
"215.88000","18.28340","2.00215"
"216.30000","18.31838","2.01576"
"216.72000","18.35335","1.87156"
"217.14000","18.38839","1.86903"
"217.56000","18.42343","1.88071"
"217.98000","18.45834","1.88845"
"218.39999","18.49338","1.89619"
"218.82001","18.52842","1.91313"
"219.24001","18.56346","1.93215"
"219.66000","18.59843","1.32957"
"220.08000","18.63335","1.33271"
"220.50000","18.66838","1.33360"
"220.92000","18.70342","1.35465"
"221.34000","18.73840","1.36479"
"221.75999","18.77337","1.38004"
"222.17999","18.80835","1.39322"
"222.60001","18.84339","1.41156"
"223.02000","18.87843","1.41738"
"223.44000","18.91346","1.42984"
"223.86000","18.94844","1.44506"
"224.28000","18.98336","1.47682"
"224.70000","19.01845","1.48632"
"225.12000","19.05349","1.50638"
"225.53999","19.08841","1.52106"
"225.96001","19.12338","1.52504"
"226.38000","19.15842","1.52993"
"226.80000","19.19346","1.53826"
"227.22000","19.22843","1.55421"
"227.64000","19.26341","1.19252"
"228.06000","19.29839","1.18850"
"228.48000","19.33342","1.19636"
"228.89999","19.36840","1.20107"
"229.32001","19.40338","1.20845"
"229.74001","19.43835","1.21504"
"230.16000","19.47339","1.21988"
"230.58000","19.50843","1.22453"
"231.00000","19.54346","1.23392"
"231.42000","19.57838","1.25509"
"231.84000","19.61336","1.26471"
"232.25999","19.64839","1.27794"
"232.67999","19.68343","1.28967"
"233.10001","19.71841","1.31196"
"233.52000","19.75339","1.32257"
"233.94000","19.78836","1.33099"
"234.36000","19.82340","1.34403"
"234.78000","19.85843","1.36153"
"235.20000","19.89335","1.37322"
"235.62000","19.92839","1.38356"
"236.03999","19.96342","1.40297"
"236.46001","19.99846","1.41091"
"236.88000","20.03344","1.41949"
"237.30000","20.06836","1.42517"
"237.72000","20.10339","1.44275"
"238.14000","20.13843","1.46746"
"238.56000","20.17341","1.47890"
"238.98000","20.20844","1.49389"
"239.39999","20.24336","1.50751"
"239.82001","20.27840","1.52021"
"240.24001","20.31343","1.52496"
"240.66000","20.34847","1.52835"
"241.08000","20.38339","1.53849"
"241.50000","20.41837","1.55130"
"241.92000","20.45346","1.57272"
"242.34000","20.48844","1.58235"
"242.75999","20.52347","1.60812"
"243.17999","20.55839","1.62559"
"243.60001","20.59337","1.63607"
"244.02000","20.62846","1.64720"
"244.44000","20.66344","1.66558"
"244.86000","20.69842","1.67786"
"245.28000","20.73339","1.68735"
"245.70000","20.76843","1.69065"
"246.12000","20.80341","1.41716"
"246.53999","20.83839","1.42028"
"246.96001","20.87336","1.43416"
"247.38000","20.90840","1.45406"
"247.80000","20.94344","1.48140"
"248.22000","20.97847","1.49527"
"248.64000","21.01339","1.51754"
"249.06000","21.04837","1.52576"
"249.48000","21.08340","1.53090"
"249.89999","21.11844","1.55463"
"250.32001","21.15342","1.57363"
"250.74001","21.18834","1.59152"
"251.16000","21.22337","1.62282"
"251.58000","21.25847","1.63155"
"252.00000","21.29344","1.64636"
"252.42000","21.32836","1.66911"
"252.84000","21.36340","1.67857"
"253.25999","21.39843","1.69343"
"253.67999","21.43347","1.71748"
"254.10001","21.46845","1.73396"
"254.52000","21.50343","1.74164"
"254.94000","21.53840","1.76065"
"255.36000","21.57338","1.78808"
"255.78000","21.60842","1.80543"
"256.20001","21.64339","1.82203"
"256.62000","21.67837","1.82684"
"257.04001","21.71335","1.82979"
"257.45999","21.74844","1.84770"
"257.88000","21.78342","1.87704"
"258.29999","21.81840","1.89051"
"258.72000","21.85337","1.90963"
"259.14001","21.88847","1.93070"
"259.56000","21.92345","1.94502"
"259.98001","21.95842","1.95092"
"260.39999","21.99340","1.95879"
"260.82001","22.02838","1.97249"
"261.23999","22.06347","1.98546"
"261.66000","22.09839","2.01466"
"262.07999","22.13337","2.03725"
"262.50000","22.16840","2.04159"
"262.92001","22.20344","2.05505"
"263.34000","22.23842","2.07852"
"263.76001","22.27340","2.09907"
"264.17999","22.30837","2.10623"
"264.60001","22.34341","2.11790"
"265.01999","22.37844","2.12911"
"265.44000","22.41342","2.13909"
"265.85999","22.44840","2.15309"
"266.28000","22.48338","2.17241"
"266.70001","22.51841","1.86444"
"267.12000","22.55345","1.87451"
"267.54001","22.58843","1.88850"
"267.95999","22.62334","1.90357"
"268.38000","22.65838","1.93287"
"268.79999","22.69342","1.94880"
"269.22000","22.72845","1.95547"
"269.64001","22.76337","1.97246"
"270.06000","22.79841","1.99003"
"270.48001","22.83344","2.02675"
"270.89999","22.86848","2.03991"
"271.32001","22.90346","2.05452"
"271.73999","22.93837","2.08591"
"272.16000","22.97341","2.10207"
"272.57999","23.00845","2.11776"
"273.00000","23.04343","2.13238"
"273.42001","23.07840","2.14576"
"273.84000","23.11338","2.17105"
"274.26001","23.14842","2.19247"
"274.67999","23.18339","2.21801"
"275.10001","23.21843","2.13777"
"275.51999","23.25340","2.14124"
"275.94000","23.28838","2.15362"
"276.35999","23.32348","2.17124"
"276.78000","23.35839","2.18766"
"277.20001","23.39343","2.20161"
"277.62000","23.42841","2.22673"
"278.04001","23.46339","2.24267"
"278.45999","23.49842","2.24966"
"278.88000","23.53340","2.25184"
"279.29999","23.56837","2.26574"
"279.72000","23.60335","2.29327"
"280.14001","23.63839","2.31180"
"280.56000","23.67343","2.33155"
"280.98001","23.70840","2.34823"
"281.39999","23.74332","2.35603"
"281.82001","23.77848","2.37040"
"282.23999","23.81345","2.38684"
"282.66000","23.84849","1.14861"
"283.07999","23.88341","1.06741"
"283.50000","23.91838","1.13529"
"283.92001","23.95342","1.21253"
"284.34000","23.98846","1.14629"
"284.76001","24.02344","1.20071"
"285.17999","24.05835","1.21149"
"285.60001","24.09339","1.28601"
"286.01999","24.12843","1.25253"
"286.44000","24.16340","1.28018"
"286.85999","24.19838","1.32939"
"287.28000","24.23336","1.33235"
"287.70001","24.26845","1.34427"
"288.12000","24.30343","1.37898"
"288.54001","24.33841","1.37253"
"288.95999","24.37338","1.38975"
"289.38000","24.40842","1.42499"
"289.79999","24.44340","1.42141"
"290.22000","24.47843","1.47042"
"290.64001","24.51341","1.47858"
"291.06000","24.54833","1.50389"
"291.48001","24.58336","1.52196"
"291.89999","24.61846","1.52673"
"292.32001","24.65344","1.54670"
"292.73999","24.68841","1.56184"
"293.16000","24.72339","1.59172"
"293.57999","24.75843","1.61412"
"294.00000","24.79346","1.50960"
"294.42001","24.82844","1.51341"
"294.84000","24.86342","1.52617"
"295.26001","24.89840","1.38000"
"295.67999","24.93343","1.40573"
"296.10001","24.96841","1.41468"
"296.51999","25.00339","1.42613"
"296.94000","25.03836","1.46970"
"297.35999","25.07346","1.48118"
"297.78000","25.10838","1.51565"
"298.20001","25.14341","1.52469"
"298.62000","25.17839","1.53643"
"299.04001","25.21343","1.55481"
"299.45999","25.24846","1.58169"
"299.88000","25.28344","1.60898"
"300.29999","25.31842","1.63015"
"300.72000","25.35339","1.64214"
"301.14001","25.38843","1.66624"
"301.56000","25.42341","1.67704"
"301.98001","25.45838","1.68905"
"302.39999","25.49336","1.71114"
"302.82001","25.52834","1.72941"
"303.23999","25.56343","1.74272"
"303.66000","25.59847","1.76393"
"304.07999","25.63339","1.79073"
"304.50000","25.66837","1.81177"
"304.92001","25.70340","1.82542"
"305.34000","25.73844","1.82858"
"305.76001","25.77341","1.84444"
"306.17999","25.80839","1.87513"
"306.60001","25.84343","1.89102"
"307.01999","25.87840","1.91695"
"307.44000","25.91338","1.93977"
"307.85999","25.94842","1.94981"
"308.28000","25.98334","1.95847"
"308.70001","26.01837","1.97453"
"309.12000","26.05347","1.98909"
"309.54001","26.08845","2.02080"
"309.95999","26.12342","2.03907"
"310.38000","26.15834","2.04555"
"310.79999","26.19349","2.06871"
"311.22000","26.22847","1.93876"
"311.64001","26.26345","1.89782"
"312.06000","26.29837","1.91122"
"312.48001","26.33340","1.93303"
"312.89999","26.36844","1.94687"
"313.32001","26.40342","1.95316"
"313.73999","26.43839","1.96539"
"314.16000","26.47337","1.86085"
"314.57999","26.50841","1.80182"
"315.00000","26.54338","1.81706"
"315.42001","26.57842","1.82672"
"315.84000","26.61334","1.83287"
"316.26001","26.64844","1.86214"
"316.67999","26.68341","1.88946"
"317.10001","26.71839","1.91768"
"317.51999","26.75342","1.94404"
"317.94000","26.78840","1.95279"
"318.35999","26.82344","1.96749"
"318.78000","26.85841","1.98706"
"319.20001","26.89345","2.02525"
"319.62000","26.92837","2.04016"
"320.04001","26.96335","2.05498"
"320.45999","26.99844","2.08723"
"320.88000","27.03348","2.10239"
"321.29999","27.06834","2.11767"
"321.72000","27.10337","2.13154"
"322.14001","27.13841","2.14378"
"322.56000","27.17344","2.16657"
"322.98001","27.20842","2.18674"
"323.39999","27.24340","2.20511"
"323.82001","27.27844","2.23419"
"324.23999","27.31342","2.24815"
"324.66000","27.34845","2.24574"
"325.07999","27.38343","2.24800"
"325.50000","27.41834","2.03849"
"325.92001","27.45338","2.03896"
"326.34000","27.48848","1.90970"
"326.76001","27.52345","1.84282"
"327.17999","27.55837","1.86756"
"327.60001","27.59335","1.88855"
"328.01999","27.62845","1.91061"
"328.44000","27.66342","1.74034"
"328.85999","27.69846","1.53751"
"329.28000","27.73337","1.54774"
"329.70001","27.76841","1.56085"
"330.12000","27.80345","1.57648"
"330.54001","27.83842","1.59221"
"330.95999","27.87334","1.61779"
"331.38000","27.90838","1.62756"
"331.79999","27.94342","1.64134"
"332.22000","27.97845","1.65423"
"332.64001","28.01343","1.67318"
"333.06000","28.04835","1.67881"
"333.48001","28.08344","1.69436"
"333.89999","28.11842","1.71034"
"334.32001","28.15346","1.72633"
"334.73999","28.18843","1.68176"
"335.16000","28.22341","1.52639"
"335.57999","28.25845","1.52786"
"336.00000","28.29337","1.53487"
"336.42001","28.32846","1.55481"
"336.84000","28.36338","1.57396"
"337.26001","28.39835","1.58933"
"337.67999","28.43345","1.61611"
"338.10001","28.46849","1.62835"
"338.51999","28.50341","1.63953"
"338.94000","28.53838","1.65423"
"339.35999","28.57342","1.67089"
"339.78000","28.60846","1.67945"
"340.20001","28.64343","1.69299"
"340.62000","28.67841","1.70980"
"341.04001","28.71345","1.72674"
"341.45999","28.74842","1.73585"
"341.88000","28.78340","1.74632"
"342.29999","28.81844","1.76589"
"342.72000","28.85335","1.78704"
"343.14001","28.88839","1.79866"
"343.56000","28.92343","1.81559"
"343.98001","28.95846","1.73871"
"344.39999","28.99338","1.74132"
"344.82001","29.02836","1.75711"
"345.23999","29.06339","1.77446"
"345.66000","29.09843","1.79189"
"346.07999","29.13347","1.80581"
"346.50000","29.16839","1.82020"
"346.92001","29.20336","1.82653"
"347.34000","29.23846","1.82784"
"347.76001","29.27343","1.83345"
"348.17999","29.30835","1.59157"
"348.60001","29.34339","1.55563"
"349.01999","29.37842","1.57107"
"349.44000","29.41340","1.57112"
"349.85999","29.44844","1.58331"
"350.28000","29.48335","1.59776"
"350.70001","29.51839","1.61659"
"351.12000","29.55343","1.62554"
"351.54001","29.58846","1.63586"
"351.95999","29.62344","1.64338"
"352.38000","29.65836","1.65640"
"352.79999","29.69345","1.67055"
"353.22000","29.72843","1.67851"
"353.64001","29.76341","1.68339"
"354.06000","29.79833","1.70019"
"354.48001","29.83343","1.31914"
"354.89999","29.86846","1.32007"
"355.32001","29.90344","1.32204"
"355.73999","29.93842","1.32930"
"356.16000","29.97339","1.33200"
"356.57999","30.00843","1.34367"
"357.00000","30.04346","1.36273"
"357.42001","30.07844","1.37040"
"357.84000","30.11342","1.38193"
"358.26001","30.14839","1.39834"
"358.67999","30.18343","1.40846"
"359.10001","30.21841","1.41574"
"359.51999","30.25338","1.42214"
"359.94000","30.28836","1.42924"
"360.35999","30.32340","1.45088"
"360.78000","30.35843","1.46969"
"361.20001","30.39347","1.47970"
"361.62000","30.42839","1.48967"
"362.04001","30.46337","1.50299"
"362.45999","30.49846","1.51417"
"362.88000","30.53344","1.52218"
"363.29999","30.56848","1.52581"
"363.72000","30.60339","1.52886"
"364.14001","30.63837","1.53623"
"364.56000","30.67346","1.54963"
"364.98001","30.70838","1.56352"
"365.39999","30.74336","1.57535"
"365.82001","30.77840","1.58257"
"366.23999","30.81343","1.60471"
"366.66000","30.84841","1.61850"
"367.07999","30.88345","1.62657"
"367.50000","30.91836","1.63396"
"367.92001","30.95346","1.33511"
"368.34000","30.98844","1.05433"
"368.76001","31.02347","1.05200"
"369.17999","31.05845","1.05384"
"369.60001","31.09337","1.05763"
"370.01999","31.12840","1.06095"
"370.44000","31.16344","1.07280"
"370.85999","31.19842","1.08980"
"371.28000","31.23334","1.10451"
"371.70001","31.26837","1.11332"
"372.12000","31.30341","1.11862"
"372.54001","31.33838","1.12186"
"372.95999","31.37336","1.12853"
"373.38000","31.40840","1.13979"
"373.79999","31.44344","1.15868"
"374.22000","31.47841","1.17056"
"374.64001","31.51345","1.18764"
"375.06000","31.54843","1.20037"
"375.48001","31.58346","1.20792"
"375.89999","31.61838","1.21492"
"376.32001","31.65342","1.21976"
"376.73999","31.68839","1.22562"
"377.16000","31.72331","1.23752"
"377.57999","31.75841","1.25021"
"378.00000","31.79344","1.26395"
"378.42001","31.82848","1.27074"
"378.84000","31.86340","1.27945"
"379.26001","31.89837","1.28887"
"379.67999","31.93347","1.29990"
"380.10001","31.96844","1.31210"
"380.51999","32.00342","1.32014"
"380.94000","32.03840","1.32683"
"381.35999","32.07338","1.33087"
"381.78000","32.10847","1.33803"
"382.20001","32.14339","1.34944"
"382.62000","32.17837","1.36130"
"383.04001","32.21341","1.37063"
"383.45999","32.24838","1.31596"
"383.88000","32.28342","1.32284"
"384.29999","32.31839","1.32850"
"384.72000","32.35331","1.33468"
"385.14001","32.38841","1.34844"
"385.56000","32.42339","1.36027"
"385.98001","32.45848","1.37006"
"386.39999","32.49346","1.37516"
"386.82001","32.52837","1.38777"
"387.23999","32.56341","1.39969"
"387.66000","32.59845","1.40858"
"388.07999","32.63342","1.41371"
"388.50000","32.66834","1.41908"
"388.92001","32.70338","1.42355"
"389.34000","32.73842","1.43172"
"389.76001","32.77340","0.99175"
"390.17999","32.80837","0.99599"
"390.60001","32.84335","1.00400"
"391.01999","32.87838","1.01383"
"391.44000","32.91348","0.96388"
"391.85999","32.94846","0.96913"
"392.28000","32.98343","0.98363"
"392.70001","33.01841","0.99589"
"393.12000","33.05339","1.00589"
"393.54001","33.08842","1.01434"
"393.95999","33.12340","1.02627"
"394.38000","33.15832","1.04263"
"394.79999","33.19335","1.05612"
"395.22000","33.22839","1.06192"
"395.64001","33.26343","1.08081"
"396.06000","33.29840","1.09704"
"396.48001","33.33338","1.11017"
"396.89999","33.36848","1.11624"
"397.32001","33.40340","1.12038"
"397.73999","33.43849","1.12631"
"398.16000","33.47341","1.13788"
"398.57999","33.50838","1.15865"
"399.00000","33.54348","1.17104"
"399.42001","33.57840","1.18868"
"399.84000","33.61332","1.20136"
"400.26001","33.64835","1.21057"
"400.67999","33.68345","1.21814"
"401.10001","33.71843","1.22227"
"401.51999","33.75340","1.22997"
"401.94000","33.78838","1.24225"
"402.35999","33.82341","1.25670"
"402.78000","33.85845","1.26830"
"403.20001","33.89349","1.27273"
"403.62000","33.92841","1.28384"
"404.04001","33.96338","1.29431"
"404.45999","33.99842","1.24209"
"404.88000","34.03340","1.23826"
"405.29999","34.06844","1.24499"
"405.72000","34.10335","1.25421"
"406.14001","34.13839","1.26503"
"406.56000","34.17342","1.27050"
"406.98001","34.20840","1.27585"
"407.39999","34.24338","1.28436"
"407.82001","34.27835","1.29272"
"408.23999","34.31339","1.30335"
"408.66000","34.34843","1.31257"
"409.07999","34.38340","1.31904"
"409.50000","34.41838","1.32520"
"409.92001","34.45342","1.32895"
"410.34000","34.48840","1.33238"
"410.76001","34.52343","1.30644"
"411.17999","34.55841","0.52804"
"411.60001","34.59333","0.53258"
"412.01999","34.62836","0.55665"
"412.44000","34.66340","0.55636"
"412.85999","34.69844","0.57851"
"413.28000","34.73336","0.58613"
"413.70001","34.76839","0.59265"
"414.12000","34.80343","0.59968"
"414.54001","34.83846","0.60308"
"414.95999","34.87344","0.61918"
"415.38000","34.90842","0.62242"
"415.79999","34.94339","0.63644"
"416.22000","34.97843","0.65167"
"416.64001","35.01341","0.62945"
"417.06000","35.04839","0.64514"
"417.48001","35.08342","0.65261"
"417.89999","35.11846","0.65947"
"418.32001","35.15343","0.67833"
"418.73999","35.18841","0.68499"
"419.16000","35.22339","0.69262"
"419.57999","35.25843","0.57669"
"420.00000","35.29340","0.58199"
"420.42001","35.32844","0.58944"
"420.84000","35.36342","0.47772"
"421.26001","35.39833","0.48536"
"421.67999","35.43343","0.48811"
"422.10001","35.46841","0.49128"
"422.51999","35.50344","0.49366"
"422.94000","35.53836","0.49299"
"423.35999","35.57340","0.49394"
"423.78000","35.60843","0.49507"
"424.20001","35.64341","0.49610"
"424.62000","35.67839","0.50221"
"425.04001","35.71336","0.50652"
"425.45999","35.74840","0.51374"
"425.88000","35.78344","0.51805"
"426.29999","35.81841","0.52580"
"426.72000","35.85339","0.53046"
"427.14001","35.88843","0.53934"
"427.56000","35.92340","0.54409"
"427.98001","35.95844","0.54856"
"428.39999","35.99342","0.54959"
"428.82001","36.02834","0.53906"
"429.23999","36.06337","0.54359"
"429.66000","36.09847","0.54916"
"430.07999","36.13345","0.55255"
"430.50000","36.16842","0.55766"
"430.92001","36.20340","0.56584"
"431.34000","36.23843","0.57366"
"431.76001","36.27347","0.58067"
"432.17999","36.30845","0.58509"
"432.60001","36.34336","0.58997"
"433.01999","36.37840","0.59224"
"433.44000","36.41344","0.59472"
"433.85999","36.44841","0.59704"
"434.28000","36.48339","0.60010"
"434.70001","36.51837","0.60465"
"435.12000","36.55341","0.60929"
"435.54001","36.58839","0.61487"
"435.95999","36.62342","0.62050"
"436.38000","36.65840","0.62685"
"436.79999","36.69337","0.63733"
"437.22000","36.72841","0.64427"
"437.64001","36.76345","0.65112"
"438.06000","36.79837","0.65787"
"438.48001","36.83328","0.66519"
"438.89999","36.86844","0.67551"
"439.32001","36.90347","0.68173"
"439.73999","36.93845","0.68739"
"440.16000","36.97337","0.69245"
"440.57999","37.00835","0.69660"
"441.00000","37.04344","0.69870"
"441.42001","37.07842","0.70142"
"441.84000","37.11340","0.70373"
"442.26001","37.14837","0.70555"
"442.67999","37.18341","0.70750"
"443.10001","37.21851","0.71060"
"443.51999","37.25343","0.71563"
"443.94000","37.28840","0.72203"
"444.35999","37.32344","0.72864"
"444.78000","37.35841","0.73515"
"445.20001","37.39339","0.74232"
"445.62000","37.42843","0.74677"
"446.04001","37.46334","0.75194"
"446.45999","37.49838","0.75425"
"446.88000","37.53342","0.76026"
"447.29999","37.56845","0.76681"
"447.72000","37.60343","0.77301"
"448.14001","37.63841","0.77938"
"448.56000","37.67344","0.78542"
"448.98001","37.70842","0.59444"
"449.39999","37.74346","0.59357"
"449.82001","37.77837","0.59532"
"450.23999","37.81342","0.59760"
"450.66000","37.84845","0.59982"
"451.07999","37.88343","0.60588"
"451.50000","37.91840","0.60940"
"451.92001","37.95338","0.61711"
"452.34000","37.98836","0.61963"
"452.76001","38.02339","0.62749"
"453.17999","38.05843","0.63863"
"453.60001","38.09335","0.64463"
"454.01999","38.12844","0.65289"
"454.44000","38.16342","0.65781"
"454.85999","38.19846","0.66862"
"455.28000","38.23337","0.67823"
"455.70001","38.26835","0.68327"
"456.12000","38.30345","0.69095"
"456.54001","38.33842","0.69456"
"456.95999","38.37340","0.69837"
"457.38000","38.40837","0.70238"
"457.79999","38.44341","0.70349"
"458.22000","38.47845","0.70550"
"458.64001","38.51343","0.70789"
"459.06000","38.54840","0.71115"
"459.48001","38.58338","0.71682"
"459.89999","38.61848","0.72530"
"460.32001","38.65345","0.73128"
"460.73999","38.68843","0.73911"
"461.16000","38.72341","0.74678"
"461.57999","38.75838","0.75083"
"462.00000","38.79342","0.75383"
"462.42001","38.82840","0.75999"
"462.84000","38.86343","0.76729"
"463.26001","38.89835","0.77252"
"463.67999","38.93333","0.77910"
"464.10001","38.96843","0.78558"
"464.51999","39.00340","0.79212"
"464.94000","39.03838","0.79826"
"465.35999","39.07336","0.80323"
"465.78000","39.10846","0.80776"
"466.20001","39.14349","0.81249"
"466.62000","39.17841","0.81678"
"467.04001","39.21338","0.82096"
"467.45999","39.24842","0.82485"
"467.88000","39.28345","0.82909"
"468.29999","39.31843","0.83477"
"468.72000","39.35335","0.83868"
"469.14001","39.38839","0.83468"
"469.56000","39.42342","0.83703"
"469.98001","39.45840","0.83871"
"470.39999","39.49344","0.84159"
"470.82001","39.52835","0.84148"
"471.23999","39.56345","0.58276"
"471.66000","39.59842","0.58320"
"472.07999","39.63346","0.58986"
"472.50000","39.66844","0.59208"
"472.92001","39.70342","0.59671"
"473.34000","39.73840","0.59801"
"473.76001","39.77343","0.60872"
"474.17999","39.80841","0.60877"
"474.60001","39.84332","0.62296"
"475.01999","39.87836","0.62124"
"475.44000","39.91340","0.63938"
"475.85999","39.94843","0.64055"
"476.28000","39.98335","0.65073"
"476.70001","40.01833","0.65796"
"477.12000","40.05343","0.66366"
"477.54001","40.08846","0.67986"
"477.95999","40.12344","0.68033"
"478.38000","40.15835","0.68878"
"478.79999","40.19339","0.69219"
"479.22000","40.22843","0.69528"
"479.64001","40.26341","0.70049"
"480.06000","40.29838","0.70099"
"480.48001","40.33336","0.70396"
"480.89999","40.36833","0.70579"
"481.32001","40.40344","0.70713"
"481.73999","40.43847","0.71237"
"482.16000","40.47338","0.71529"
"482.57999","40.50836","0.72078"
"483.00000","40.54346","0.72939"
"483.42001","40.57844","0.73268"
"483.84000","40.61341","0.74021"
"484.26001","40.64839","0.74749"
"484.67999","40.68337","0.74961"
"485.10001","40.71841","0.75339"
"485.51999","40.75338","0.75768"
"485.94000","40.78842","0.76110"
"486.35999","40.82339","0.76841"
"486.78000","40.85843","0.77554"
"487.20001","40.89341","0.78044"
"487.62000","40.92844","0.78728"
"488.04001","40.96342","0.79596"
"488.45999","40.99840","0.80022"
"488.88000","41.03344","0.80386"
"489.29999","41.06842","0.80817"
"489.72000","41.10345","0.81173"
"490.14001","41.13837","0.81512"
"490.56000","41.17347","0.81873"
"490.98001","41.20844","0.82199"
"491.39999","41.24342","0.82505"
"491.82001","41.27834","0.82923"
"492.23999","41.31337","0.83450"
"492.66000","41.34841","0.84031"
"493.07999","41.38345","0.84700"
"493.50000","41.41842","0.85168"
"493.92001","41.45334","0.85559"
"494.34000","41.48838","0.86123"
"494.76001","41.52341","0.86750"
"495.17999","41.55839","0.87642"
"495.60001","41.59336","0.88384"
"496.01999","41.62840","0.89089"
"496.44000","41.66344","0.89712"
"496.85999","41.69842","0.90320"
"497.28000","41.73339","0.90688"
"497.70001","41.76837","0.90819"
"498.12000","41.80335","0.89649"
"498.54001","41.83839","0.90089"
"498.95999","41.87342","0.90530"
"499.38000","41.90840","0.90744"
"499.79999","41.94337","0.90834"
"500.22000","41.97841","0.90868"
"500.64001","42.01345","0.90872"
"501.06000","42.04848","0.90906"
"501.48001","42.08340","0.91011"
"501.89999","42.11838","0.91191"
"502.32001","42.15342","0.91454"
"502.73999","42.18845","0.91733"
"503.16000","42.22343","0.80530"
"503.57999","42.25840","0.80773"
"504.00000","42.29338","0.80884"
"504.42001","42.32835","0.81326"
"504.84000","42.36340","0.81844"
"505.26001","42.39843","0.82385"
"505.67999","42.43341","0.82906"
"506.10001","42.46839","0.83760"
"506.51999","42.50343","0.84812"
"506.94000","42.53840","0.85351"
"507.35999","42.57332","0.86043"
"507.78000","42.60847","0.86966"
"508.20001","42.64345","0.87992"
"508.62000","42.67842","0.88761"
"509.04001","42.71334","0.89593"
"509.45999","42.74838","0.90370"
"509.88000","42.78342","0.90748"
"510.29999","42.81845","0.90851"
"510.72000","42.85337","0.90885"
"511.14001","42.88840","0.90991"
"511.56000","42.92344","0.91242"
"511.98001","42.95842","0.91853"
"512.40002","42.99346","0.92609"
"512.82001","43.02843","0.93189"
"513.23999","43.06341","0.57948"
"513.65997","43.09845","0.58213"
"514.08002","43.13343","0.58677"
"514.50000","43.16846","0.58651"
"514.91998","43.20338","0.58981"
"515.34003","43.23836","0.59271"
"515.76001","43.27345","0.59446"
"516.17999","43.30843","0.59717"
"516.59998","43.34340","0.60033"
"517.02002","43.37838","0.60492"
"517.44000","43.41342","0.61151"
"517.85999","43.44846","0.61672"
"518.28003","43.48343","0.62257"
"518.70001","43.51841","0.62903"
"519.12000","43.55338","0.63704"
"519.53998","43.58842","0.64611"
"519.96002","43.62346","0.65084"
"520.38000","43.65837","0.65747"
"520.79999","43.69336","0.66585"
"521.21997","43.72839","0.67498"
"521.64001","43.76337","0.68245"
"522.06000","43.79840","0.68769"
"522.47998","43.83338","0.69281"
"522.90002","43.86835","0.69714"
"523.32001","43.90345","0.70036"
"523.73999","43.93843","0.70294"
"524.15997","43.97335","0.70499"
"524.58002","44.00838","0.70676"
"525.00000","44.04348","0.70953"
"525.41998","44.07840","0.71388"
"525.84003","44.11343","0.71907"
"526.26001","44.14835","0.72527"
"526.67999","44.18339","0.73039"
"527.09998","44.21842","0.73722"
"527.52002","44.25340","0.74298"
"527.94000","44.28838","0.74799"
"528.35999","44.32336","0.75135"
"528.78003","44.35839","0.75447"
"529.20001","44.39349","0.75510"
"529.62000","44.42847","0.75870"
"530.03998","44.46339","0.76405"
"530.46002","44.49842","0.77048"
"530.88000","44.53346","0.77564"
"531.29999","44.56837","0.78237"
"531.71997","44.60341","0.78972"
"532.14001","44.63833","0.79680"
"532.56000","44.67336","0.80145"
"532.97998","44.70846","0.80556"
"533.40002","44.74344","0.80947"
"533.82001","44.77842","0.81410"
"534.23999","44.81339","0.81785"
"534.65997","44.84849","0.82139"
"535.08002","44.88341","0.82505"
"535.50000","44.91838","0.82951"
"535.91998","44.95342","0.83451"
"536.34003","44.98840","0.84278"
"536.76001","45.02343","0.27098"
"537.17999","45.05841","0.28292"
"537.59998","45.09339","0.28687"
"538.02002","45.12836","0.28542"
"538.44000","45.16340","0.28798"
"538.85999","45.19843","0.28838"
"539.28003","45.23347","0.28903"
"539.70001","45.26839","0.29466"
"540.12000","45.30342","0.29420"
"540.53998","45.33840","0.30483"
"540.96002","45.37344","0.30978"
"541.38000","45.40842","0.32687"
"541.79999","45.44339","0.33003"
"542.21997","45.47842","0.33922"
"542.64001","45.51340","0.34215"
"543.06000","45.54845","0.35060"
"543.47998","45.58342","0.35435"
"543.90002","45.61834","0.36749"
"544.32001","45.65343","0.37423"
"544.73999","45.68841","0.38215"
"545.15997","45.72339","0.38647"
"545.58002","45.75837","0.39078"
"546.00000","45.79340","0.39622"
"546.41998","45.82844","0.39891"
"546.84003","45.86341","0.40286"
"547.26001","45.89839","0.40620"
"547.67999","45.93343","0.40792"
"548.09998","45.96841","0.41177"
"548.52002","46.00338","0.41760"
"548.94000","46.03842","0.42168"
"549.35999","46.07333","0.42718"
"549.78003","46.10837","0.43364"
"550.20001","46.14341","0.43763"
"550.62000","46.17844","0.44040"
"551.03998","46.21342","0.44225"
"551.46002","46.24834","0.44435"
"551.88000","46.28344","0.44903"
"552.29999","46.31847","0.45467"
"552.71997","46.35345","0.45982"
"553.14001","46.38843","0.46503"
"553.56000","46.42340","0.46873"
"553.97998","46.45850","0.47591"
"554.40002","46.49342","0.48070"
"554.82001","46.52840","0.48511"
"555.23999","46.56337","0.48649"
"555.65997","46.59841","0.48840"
"556.08002","46.63345","0.49032"
"556.50000","46.66842","0.49216"
"556.91998","46.70333","0.49444"
"557.34003","46.73843","0.50056"
"557.76001","46.77341","0.50581"
"558.17999","46.80845","0.51051"
"558.59998","46.84343","0.51612"
"559.02002","46.87840","0.52042"
"559.44000","46.91344","0.52545"
"559.85999","46.94842","0.52934"
"560.28003","46.98339","0.53350"
"560.70001","47.01837","0.53657"
"561.12000","47.05334","0.54194"
"561.53998","47.08844","0.54675"
"561.96002","47.12342","0.54925"
"562.38000","47.15834","0.55178"
"562.79999","47.19331","0.55410"
"563.21997","47.22841","0.55725"
"563.64001","47.26345","0.56189"
"564.06000","47.29842","0.56688"
"564.47998","47.33340","0.57142"
"564.90002","47.36844","0.57705"
"565.32001","47.40347","0.58202"
"565.73999","47.43839","0.59305"
"566.15997","47.47343","0.53238"
"566.58002","47.50835","0.53368"
"567.00000","47.54338","0.53786"
"567.41998","47.57848","0.54175"
"567.84003","47.61346","0.54615"
"568.26001","47.64837","0.54823"
"568.67999","47.68335","0.55147"
"569.09998","47.71844","0.55427"
"569.52002","47.75342","0.55841"
"569.94000","47.78846","0.56373"
"570.35999","47.82338","0.56961"
"570.78003","47.85835","0.57491"
"571.20001","47.89345","0.57854"
"571.62000","47.92842","0.58276"
"572.03998","47.96334","0.58637"
"572.46002","47.99832","0.58930"
"572.88000","48.03341","0.59163"
"573.29999","48.06839","0.59330"
"573.71997","48.10343","0.59461"
"574.14001","48.13835","0.59642"
"574.56000","48.17339","0.59791"
"574.97998","48.20842","0.59965"
"575.40002","48.24346","0.60346"
"575.82001","48.27843","0.60714"
"576.23999","48.31341","0.61058"
"576.65997","48.34845","0.61482"
"577.08002","48.38342","0.61842"
"577.50000","48.41846","0.62322"
"577.91998","48.45338","0.63022"
"578.34003","48.48836","0.63718"
"578.76001","48.52339","0.64259"
"579.17999","48.55843","0.64826"
"579.59998","48.59340","0.65261"
"580.02002","48.62832","0.65845"
"580.44000","48.66341","0.66391"
"580.85999","48.69839","0.67107"
"581.28003","48.73343","0.67644"
"581.70001","48.76841","0.53299"
"582.12000","48.80344","0.54565"
"582.53998","48.83842","0.54624"
"582.96002","48.87346","0.55558"
"583.38000","48.90837","0.55978"
"583.79999","48.94335","0.57028"
"584.21997","48.97839","0.58112"
"584.64001","49.01342","0.58441"
"585.06000","49.04840","0.59123"
"585.47998","49.08338","0.59222"
"585.90002","49.11836","0.59605"
"586.32001","49.15345","0.59721"
"586.73999","49.18843","0.60304"
"587.15997","49.22341","0.60463"
"587.58002","49.25838","0.61204"
"588.00000","49.29336","0.61503"
"588.41998","49.32845","0.62111"
"588.84003","49.36343","0.62575"
"589.26001","49.39835","0.63337"
"589.67999","49.43339","0.64107"
"590.09998","49.46837","0.64734"
"590.52002","49.50346","0.65173"
"590.94000","49.53838","0.65651"
"591.35999","49.57335","0.66380"
"591.78003","49.60839","0.67087"
"592.20001","49.64343","0.67896"
"592.62000","49.67846","0.68311"
"593.03998","49.71344","0.68757"
"593.46002","49.74842","0.69205"
"593.88000","49.78346","0.69540"
"594.29999","49.81844","0.69844"
"594.71997","49.85340","0.70066"
"595.14001","49.88838","0.70297"
"595.56000","49.92336","0.70459"
"595.97998","49.95846","0.70579"
"596.40002","49.99343","0.70773"
"596.82001","50.02841","0.71003"
"597.23999","50.06334","0.71418"
"597.65997","50.09843","0.71910"
"598.08002","50.13347","0.72408"
"598.50000","50.16844","0.72983"
"598.91998","50.20342","0.73455"
"599.34003","50.23845","0.73997"
"599.76001","50.27343","0.74504"
"600.17999","50.30841","0.74917"
"600.59998","50.34344","0.75184"
"601.02002","50.37830","0.75470"
"601.44000","50.41334","0.75939"
"601.85999","50.44837","0.76406"
"602.28003","50.48341","0.76976"
"602.70001","50.51839","0.77444"
"603.12000","50.55336","0.77895"
"603.53998","50.58840","0.78416"
"603.96002","50.62338","0.79060"
"604.38000","50.65847","0.79654"
"604.79999","50.69340","0.61789"
"605.21997","50.72837","0.61523"
"605.64001","50.76347","0.21449"
"606.06000","50.79845","0.18290"
"606.47998","50.83336","0.19342"
"606.90002","50.86840","0.22409"
"607.32001","50.90343","0.19894"
"607.73999","50.93841","0.19633"
"608.15997","50.97345","0.20062"
"608.58002","51.00837","0.21437"
"609.00000","51.04340","0.21745"
"609.41998","51.07844","0.22534"
"609.84003","51.11348","0.23234"
"610.26001","51.14845","0.22675"
"610.67999","51.18336","0.23540"
"611.09998","51.21846","0.25060"
"611.52002","51.25344","0.24433"
"611.94000","51.28842","0.24372"
"612.35999","51.32333","0.26221"
"612.78003","51.35844","0.26915"
"613.20001","51.39341","0.26582"
"613.62000","51.42845","0.27650"
"614.03998","51.46342","0.28458"
"614.46002","51.49840","0.28449"
"614.88000","51.53337","0.28785"
"615.29999","51.56847","0.28802"
"615.71997","51.60345","0.28802"
"616.14001","51.63843","0.28823"
"616.56000","51.67340","0.28811"
"616.97998","51.70838","0.28838"
"617.40002","51.74342","0.28895"
"617.82001","51.77845","0.28957"
"618.23999","51.81331","0.29313"
"618.65997","51.84840","0.29750"
"619.08002","51.88344","0.30639"
"619.50000","51.91842","0.31014"
"619.91998","51.95340","0.31250"
"620.34003","51.98838","0.31345"
"620.76001","52.02341","0.31667"
"621.17999","52.05845","0.32783"
"621.59998","52.09343","0.33455"
"622.02002","52.12840","0.34133"
"622.44000","52.16338","0.34308"
"622.85999","52.19847","0.34573"
"623.28003","52.23345","0.34517"
"623.70001","52.26837","0.35059"
"624.12000","52.30341","0.35984"
"624.53998","52.33844","0.36936"
"624.71002","52.35249","0.36636"