File: old/analysis_20190400_old/old/24BG_95
"","End.date","X12.21.2016"
"Specimen label","24BG_95",""
"Maximum Load","0.00842","N"
"Time","Extension","Load"
"(s)","(mm)","(N)"
"0.00000","-0.00006","0.00061"
"0.06600","0.00161","0.00098"
"0.13200","0.00676","0.00137"
"0.19800","0.01393","0.00121"
"0.26400","0.02099","0.00070"
"0.33000","0.02738","0.00110"
"0.39600","0.03318","0.00179"
"0.46200","0.03880","0.00120"
"0.52800","0.04424","0.00177"
"0.59400","0.04969","0.00153"
"0.66000","0.05513","0.00183"
"0.72600","0.06063","0.00135"
"0.79200","0.06619","0.00141"
"0.85800","0.07169","0.00197"
"0.92400","0.07719","0.00198"
"0.99000","0.08269","0.00194"
"1.05600","0.08819","0.00188"
"1.12200","0.09363","0.00189"
"1.18800","0.09919","0.00218"
"1.25400","0.10463","0.00186"
"1.32000","0.11019","0.00201"
"1.38600","0.11569","0.00245"
"1.45200","0.12119","0.00233"
"1.51800","0.12675","0.00224"
"1.58400","0.13219","0.00215"
"1.65000","0.13764","0.00267"
"1.71600","0.14314","0.00242"
"1.78200","0.14864","0.00217"
"1.84800","0.15414","0.00240"
"1.91400","0.15970","0.00258"
"1.98000","0.16514","0.00297"
"2.04600","0.17070","0.00255"
"2.11200","0.17614","0.00260"
"2.17800","0.18170","0.00236"
"2.24400","0.18714","0.00271"
"2.31000","0.19258","0.00260"
"2.37600","0.19820","0.00283"
"2.44200","0.20364","0.00281"
"2.50800","0.20920","0.00273"
"2.57400","0.21464","0.00301"
"2.64000","0.22020","0.00254"
"2.70600","0.22565","0.00259"
"2.77200","0.23121","0.00314"
"2.83800","0.23659","0.00301"
"2.90400","0.24209","0.00274"
"2.97000","0.24765","0.00273"
"3.03600","0.25321","0.00265"
"3.10200","0.25865","0.00317"
"3.16800","0.26415","0.00337"
"3.23400","0.26965","0.00341"
"3.30000","0.27515","0.00307"
"3.36600","0.28059","0.00320"
"3.43200","0.28615","0.00355"
"3.49800","0.29165","0.00331"
"3.56400","0.29721","0.00322"
"3.63000","0.30265","0.00325"
"3.69600","0.30822","0.00285"
"3.76200","0.31366","0.00340"
"3.82800","0.31916","0.00311"
"3.89400","0.32460","0.00320"
"3.96000","0.33016","0.00371"
"4.02600","0.33566","0.00331"
"4.09200","0.34122","0.00338"
"4.15800","0.34666","0.00335"
"4.22400","0.35222","0.00321"
"4.29000","0.35766","0.00349"
"4.35600","0.36316","0.00315"
"4.42200","0.36860","0.00330"
"4.48800","0.37416","0.00351"
"4.55400","0.37960","0.00337"
"4.62000","0.38516","0.00373"
"4.68600","0.39066","0.00325"
"4.75200","0.39617","0.00368"
"4.81800","0.40167","0.00394"
"4.88400","0.40711","0.00367"
"4.95000","0.41267","0.00347"
"5.01600","0.41811","0.00354"
"5.08200","0.42367","0.00406"
"5.14800","0.42917","0.00305"
"5.21400","0.43473","0.00363"
"5.28000","0.44017","0.00183"
"5.34600","0.44573","0.00198"
"5.41200","0.45111","-0.00098"
"5.47800","0.45661","0.00494"
"5.54400","0.46211","0.00378"
"5.61000","0.46767","0.00347"
"5.67600","0.47317","0.00321"
"5.74200","0.47868","0.00317"
"5.80800","0.48418","0.00315"
"5.87400","0.48968","0.00435"
"5.94000","0.49518","0.00464"
"6.00600","0.50062","0.00388"
"6.07200","0.50612","0.00377"
"6.13800","0.51162","0.00347"
"6.20400","0.51718","0.00321"
"6.27000","0.52268","0.00335"
"6.33600","0.52818","0.00411"
"6.40200","0.53368","0.00447"
"6.46800","0.53912","0.00393"
"6.53400","0.54468","0.00361"
"6.60000","0.55012","0.00331"
"6.66600","0.55568","0.00353"
"6.73200","0.56112","0.00371"
"6.79800","0.56669","0.00401"
"6.86400","0.57219","0.00373"
"6.93000","0.57769","0.00399"
"6.99600","0.58319","0.00350"
"7.06200","0.58863","0.00376"
"7.12800","0.59413","0.00361"
"7.19400","0.59957","0.00406"
"7.26000","0.60513","0.00364"
"7.32600","0.61063","0.00407"
"7.39200","0.61613","0.00394"
"7.45800","0.62163","0.00375"
"7.52400","0.62719","0.00383"
"7.59000","0.63257","0.00372"
"7.65600","0.63813","0.00404"
"7.72200","0.64357","0.00421"
"7.78800","0.64919","0.00366"
"7.85400","0.65470","0.00359"
"7.92000","0.66020","0.00410"
"7.98600","0.66564","0.00367"
"8.05200","0.67114","0.00412"
"8.11800","0.67664","0.00429"
"8.18400","0.68208","0.00428"
"8.25000","0.68764","0.00447"
"8.31600","0.69314","0.00403"
"8.38200","0.69864","0.00378"
"8.44800","0.70414","0.00398"
"8.51400","0.70970","0.00398"
"8.58000","0.71514","0.00412"
"8.64600","0.72064","0.00398"
"8.71200","0.72614","0.00399"
"8.77800","0.73158","0.00418"
"8.84400","0.73709","0.00467"
"8.91000","0.74265","0.00448"
"8.97600","0.74815","0.00427"
"9.04200","0.75371","0.00487"
"9.10800","0.75921","0.00460"
"9.17400","0.76465","0.00409"
"9.24000","0.77015","0.00446"
"9.30600","0.77559","0.00450"
"9.37200","0.78115","0.00431"
"9.43800","0.78665","0.00433"
"9.50400","0.79221","0.00451"
"9.57000","0.79771","0.00461"
"9.63600","0.80321","0.00460"
"9.70200","0.80865","0.00450"
"9.76800","0.81415","0.00445"
"9.83400","0.81965","0.00476"
"9.90000","0.82510","0.00471"
"9.96600","0.83066","0.00422"
"10.03200","0.83616","0.00473"
"10.09800","0.84172","0.00461"
"10.16400","0.84722","0.00456"
"10.23000","0.85266","0.00463"
"10.29600","0.85810","0.00436"
"10.36200","0.86360","0.00465"
"10.42800","0.86910","0.00471"
"10.49400","0.87466","0.00399"
"10.56000","0.88016","0.00485"
"10.62600","0.88566","0.00477"
"10.69200","0.89116","0.00440"
"10.75800","0.89666","0.00473"
"10.82400","0.90210","0.00465"
"10.89000","0.90761","0.00501"
"10.95600","0.91311","0.00495"
"11.02200","0.91867","0.00443"
"11.08800","0.92417","0.00497"
"11.15400","0.92967","0.00506"
"11.22000","0.93517","0.00487"
"11.28600","0.94067","0.00471"
"11.35200","0.94617","0.00483"
"11.41800","0.95161","0.00479"
"11.48400","0.95711","0.00471"
"11.55000","0.96261","0.00481"
"11.61600","0.96817","0.00491"
"11.68200","0.97367","0.00509"
"11.74800","0.97917","0.00493"
"11.81400","0.98473","0.00504"
"11.88000","0.99017","0.00539"
"11.94600","0.99568","0.00475"
"12.01200","1.00118","0.00465"
"12.07800","1.00674","0.00477"
"12.14400","1.01218","0.00492"
"12.21000","1.01768","0.00522"
"12.27600","1.02324","0.00501"
"12.34200","1.02868","0.00513"
"12.40800","1.03418","0.00468"
"12.47400","1.03962","0.00509"
"12.54000","1.04512","0.00543"
"12.60600","1.05062","0.00457"
"12.67200","1.05618","0.00508"
"12.73800","1.06168","0.00466"
"12.80400","1.06712","0.00509"
"12.87000","1.07262","0.00485"
"12.93600","1.07812","0.00512"
"13.00200","1.08363","0.00524"
"13.06800","1.08907","0.00538"
"13.13400","1.09469","0.00526"
"13.20000","1.10013","0.00532"
"13.26600","1.10569","0.00514"
"13.33200","1.11119","0.00554"
"13.39800","1.11669","0.00538"
"13.46400","1.12213","0.00539"
"13.53000","1.12769","0.00535"
"13.59600","1.13313","0.00530"
"13.66200","1.13863","0.00535"
"13.72800","1.14413","0.00500"
"13.79400","1.14969","0.00521"
"13.86000","1.15513","0.00508"
"13.92600","1.16063","0.00515"
"13.99200","1.16619","0.00508"
"14.05800","1.17158","0.00497"
"14.12400","1.17714","0.00514"
"14.19000","1.18258","0.00517"
"14.25600","1.18820","0.00511"
"14.32200","1.19370","0.00511"
"14.38800","1.19920","0.00512"
"14.45400","1.20470","0.00515"
"14.52000","1.21014","0.00504"
"14.58600","1.21564","0.00495"
"14.65200","1.22114","0.00538"
"14.71800","1.22664","0.00518"
"14.78400","1.23214","0.00522"
"14.85000","1.23770","0.00517"
"14.91600","1.24314","0.00508"
"14.98200","1.24864","0.00517"
"15.04800","1.25415","0.00535"
"15.11400","1.25965","0.00528"
"15.18000","1.26509","0.00529"
"15.24600","1.27059","0.00539"
"15.31200","1.27615","0.00520"
"15.37800","1.28165","0.00502"
"15.44400","1.28715","0.00551"
"15.51000","1.29265","0.00486"
"15.57600","1.29821","0.00551"
"15.64200","1.30359","0.00516"
"15.70800","1.30915","0.00525"
"15.77400","1.31459","0.00567"
"15.84000","1.32021","0.00539"
"15.90600","1.32571","0.00555"
"15.97200","1.33121","0.00522"
"16.03800","1.33671","0.00523"
"16.10400","1.34222","0.00537"
"16.17000","1.34772","0.00519"
"16.23600","1.35316","0.00574"
"16.30200","1.35860","0.00498"
"16.36800","1.36416","0.00526"
"16.43400","1.36966","0.00555"
"16.50000","1.37516","0.00519"
"16.56600","1.38066","0.00530"
"16.63200","1.38616","0.00568"
"16.69800","1.39166","0.00546"
"16.76400","1.39716","0.00534"
"16.83000","1.40266","0.00530"
"16.89600","1.40810","0.00556"
"16.96200","1.41366","0.00534"
"17.02800","1.41916","0.00558"
"17.09400","1.42466","0.00549"
"17.16000","1.43023","0.00504"
"17.22600","1.43567","0.00587"
"17.29200","1.44111","0.00566"
"17.35800","1.44661","0.00562"
"17.42400","1.45217","0.00580"
"17.49000","1.45761","0.00563"
"17.55600","1.46323","0.00552"
"17.62200","1.46861","0.00547"
"17.68800","1.47423","0.00547"
"17.75400","1.47961","0.00577"
"17.82000","1.48511","0.00564"
"17.88600","1.49061","0.00552"
"17.95200","1.49611","0.00556"
"18.01800","1.50161","0.00562"
"18.08400","1.50717","0.00581"
"18.15000","1.51268","0.00592"
"18.21600","1.51818","0.00573"
"18.28200","1.52368","0.00538"
"18.34800","1.52918","0.00565"
"18.41400","1.53462","0.00568"
"18.48000","1.54012","0.00545"
"18.54600","1.54562","0.00538"
"18.61200","1.55118","0.00587"
"18.67800","1.55668","0.00566"
"18.74400","1.56218","0.00549"
"18.81000","1.56768","0.00564"
"18.87600","1.57312","0.00561"
"18.94200","1.57862","0.00540"
"19.00800","1.58412","0.00552"
"19.07400","1.58968","0.00579"
"19.14000","1.59518","0.00584"
"19.20600","1.60063","0.00534"
"19.27200","1.60619","0.00558"
"19.33800","1.61169","0.00577"
"19.40400","1.61719","0.00572"
"19.47000","1.62263","0.00547"
"19.53600","1.62813","0.00558"
"19.60200","1.63363","0.00538"
"19.66800","1.63919","0.00582"
"19.73400","1.64469","0.00568"
"19.80000","1.65013","0.00586"
"19.86600","1.65569","0.00526"
"19.93200","1.66113","0.00578"
"19.99800","1.66663","0.00577"
"20.06400","1.67207","0.00556"
"20.13000","1.67763","0.00582"
"20.19600","1.68314","0.00569"
"20.26200","1.68864","0.00569"
"20.32800","1.69414","0.00541"
"20.39400","1.69964","0.00578"
"20.46000","1.70514","0.00601"
"20.52600","1.71064","0.00568"
"20.59200","1.71614","0.00572"
"20.65800","1.72158","0.00547"
"20.72400","1.72714","0.00581"
"20.79000","1.73258","0.00609"
"20.85600","1.73820","0.00612"
"20.92200","1.74364","0.00570"
"20.98800","1.74920","0.00588"
"21.05400","1.75458","0.00578"
"21.12000","1.76008","0.00535"
"21.18600","1.76564","0.00561"
"21.25200","1.77115","0.00573"
"21.31800","1.77665","0.00581"
"21.38400","1.78209","0.00580"
"21.45000","1.78765","0.00586"
"21.51600","1.79309","0.00578"
"21.58200","1.79865","0.00592"
"21.64800","1.80409","0.00594"
"21.71400","1.80965","0.00588"
"21.78000","1.81515","0.00577"
"21.84600","1.82071","0.00570"
"21.91200","1.82615","0.00596"
"21.97800","1.83165","0.00592"
"22.04400","1.83715","0.00591"
"22.11000","1.84259","0.00615"
"22.17600","1.84815","0.00584"
"22.24200","1.85360","0.00556"
"22.30800","1.85916","0.00600"
"22.37400","1.86466","0.00564"
"22.44000","1.87022","0.00603"
"22.50600","1.87566","0.00608"
"22.57200","1.88122","0.00579"
"22.63800","1.88666","0.00592"
"22.70400","1.89216","0.00607"
"22.77000","1.89766","0.00583"
"22.83600","1.90316","0.00575"
"22.90200","1.90872","0.00627"
"22.96800","1.91416","0.00597"
"23.03400","1.91972","0.00609"
"23.10000","1.92516","0.00584"
"23.16600","1.93066","0.00574"
"23.23200","1.93610","0.00624"
"23.29800","1.94167","0.00596"
"23.36400","1.94717","0.00595"
"23.43000","1.95273","0.00599"
"23.49600","1.95817","0.00632"
"23.56200","1.96367","0.00611"
"23.62800","1.96911","0.00584"
"23.69400","1.97461","0.00615"
"23.76000","1.98011","0.00629"
"23.82600","1.98561","0.00656"
"23.89200","1.99111","0.00595"
"23.95800","1.99667","0.00584"
"24.02400","2.00217","0.00633"
"24.09000","2.00773","0.00605"
"24.15600","2.01317","0.00616"
"24.22200","2.01867","0.00587"
"24.28800","2.02411","0.00600"
"24.35400","2.02962","0.00630"
"24.42000","2.03518","0.00591"
"24.48600","2.04068","0.00591"
"24.55200","2.04618","0.00588"
"24.61800","2.05168","0.00592"
"24.68400","2.05718","0.00635"
"24.75000","2.06268","0.00591"
"24.81600","2.06812","0.00599"
"24.88200","2.07362","0.00612"
"24.94800","2.07912","0.00617"
"25.01400","2.08468","0.00641"
"25.08000","2.09018","0.00634"
"25.14600","2.09568","0.00604"
"25.21200","2.10118","0.00604"
"25.27800","2.10662","0.00642"
"25.34400","2.11213","0.00603"
"25.41000","2.11763","0.00638"
"25.47600","2.12313","0.00603"
"25.54200","2.12863","0.00588"
"25.60800","2.13425","0.00617"
"25.67400","2.13963","0.00613"
"25.74000","2.14519","0.00637"
"25.80600","2.15063","0.00622"
"25.87200","2.15613","0.00614"
"25.93800","2.16157","0.00625"
"26.00400","2.16707","0.00613"
"26.07000","2.17257","0.00619"
"26.13600","2.17813","0.00623"
"26.20200","2.18363","0.00608"
"26.26800","2.18919","0.00624"
"26.33400","2.19463","0.00586"
"26.40000","2.20014","0.00636"
"26.46600","2.20564","0.00610"
"26.53200","2.21114","0.00654"
"26.59800","2.21664","0.00613"
"26.66400","2.22214","0.00634"
"26.73000","2.22770","0.00655"
"26.79600","2.23320","0.00669"
"26.86200","2.23870","0.00621"
"26.92800","2.24414","0.00600"
"26.99400","2.24964","0.00636"
"27.06000","2.25514","0.00584"
"27.12600","2.26064","0.00654"
"27.19200","2.26620","0.00613"
"27.25800","2.27164","0.00630"
"27.32400","2.27720","0.00624"
"27.39000","2.28264","0.00651"
"27.45600","2.28821","0.00624"
"27.52200","2.29365","0.00615"
"27.58800","2.29909","0.00619"
"27.65400","2.30465","0.00654"
"27.72000","2.31015","0.00667"
"27.78600","2.31565","0.00613"
"27.85200","2.32115","0.00647"
"27.91800","2.32665","0.00625"
"27.98400","2.33215","0.00626"
"28.05000","2.33759","0.00640"
"28.11600","2.34309","0.00647"
"28.18200","2.34859","0.00649"
"28.24800","2.35415","0.00619"
"28.31400","2.35965","0.00629"
"28.38000","2.36515","0.00602"
"28.44600","2.37066","0.00652"
"28.51200","2.37616","0.00637"
"28.57800","2.38166","0.00649"
"28.64400","2.38710","0.00660"
"28.71000","2.39260","0.00634"
"28.77600","2.39816","0.00649"
"28.84200","2.40366","0.00631"
"28.90800","2.40922","0.00666"
"28.97400","2.41466","0.00639"
"29.04000","2.42022","0.00621"
"29.10600","2.42566","0.00599"
"29.17200","2.43116","0.00640"
"29.23800","2.43660","0.00651"
"29.30400","2.44216","0.00663"
"29.37000","2.44772","0.00634"
"29.43600","2.45316","0.00638"
"29.50200","2.45867","0.00657"
"29.56800","2.46417","0.00626"
"29.63400","2.46967","0.00686"
"29.70000","2.47511","0.00690"
"29.76600","2.48067","0.00613"
"29.83200","2.48611","0.00632"
"29.89800","2.49173","0.00666"
"29.96400","2.49717","0.00624"
"30.03000","2.50267","0.00637"
"30.09600","2.50817","0.00643"
"30.16200","2.51367","0.00623"
"30.22800","2.51917","0.00681"
"30.29400","2.52461","0.00682"
"30.36000","2.53011","0.00616"
"30.42600","2.53567","0.00670"
"30.49200","2.54123","0.00648"
"30.55800","2.54668","0.00630"
"30.62400","2.55218","0.00638"
"30.69000","2.55762","0.00668"
"30.75600","2.56318","0.00649"
"30.82200","2.56862","0.00671"
"30.88800","2.57418","0.00652"
"30.95400","2.57962","0.00657"
"31.02000","2.58518","0.00618"
"31.08600","2.59068","0.00655"
"31.15200","2.59618","0.00647"
"31.21800","2.60162","0.00638"
"31.28400","2.60712","0.00631"
"31.35000","2.61256","0.00693"
"31.41600","2.61818","0.00656"
"31.48200","2.62368","0.00648"
"31.54800","2.62919","0.00629"
"31.61400","2.63463","0.00662"
"31.68000","2.64019","0.00657"
"31.74600","2.64563","0.00666"
"31.81200","2.65113","0.00677"
"31.87800","2.65657","0.00654"
"31.94400","2.66213","0.00662"
"32.01000","2.66769","0.00692"
"32.07600","2.67319","0.00659"
"32.14200","2.67869","0.00668"
"32.20800","2.68413","0.00659"
"32.27400","2.68963","0.00659"
"32.34000","2.69513","0.00645"
"32.40600","2.70063","0.00666"
"32.47200","2.70613","0.00656"
"32.53800","2.71163","0.00663"
"32.60400","2.71714","0.00641"
"32.67000","2.72264","0.00654"
"32.73600","2.72820","0.00636"
"32.80200","2.73364","0.00655"
"32.86800","2.73908","0.00650"
"32.93400","2.74458","0.00665"
"33.00000","2.75008","0.00685"
"33.06600","2.75570","0.00691"
"33.13200","2.76120","0.00630"
"33.19800","2.76670","0.00671"
"33.26400","2.77214","0.00624"
"33.33000","2.77770","0.00666"
"33.39600","2.78314","0.00674"
"33.46200","2.78864","0.00655"
"33.52800","2.79408","0.00678"
"33.59400","2.79959","0.00690"
"33.66000","2.80521","0.00670"
"33.72600","2.81065","0.00659"
"33.79200","2.81621","0.00687"
"33.85800","2.82165","0.00693"
"33.92400","2.82715","0.00684"
"33.99000","2.83265","0.00674"
"34.05600","2.83815","0.00701"
"34.12200","2.84359","0.00660"
"34.18800","2.84915","0.00646"
"34.25400","2.85465","0.00671"
"34.32000","2.86015","0.00674"
"34.38600","2.86565","0.00671"
"34.45200","2.87109","0.00687"
"34.51800","2.87659","0.00689"
"34.58400","2.88209","0.00707"
"34.65000","2.88766","0.00660"
"34.71600","2.89316","0.00688"
"34.78200","2.89872","0.00681"
"34.84800","2.90416","0.00694"
"34.91400","2.90972","0.00690"
"34.98000","2.91516","0.00644"
"35.04600","2.92060","0.00663"
"35.11200","2.92610","0.00719"
"35.17800","2.93160","0.00712"
"35.24400","2.93716","0.00673"
"35.31000","2.94266","0.00669"
"35.37600","2.94816","0.00666"
"35.44200","2.95372","0.00675"
"35.50800","2.95916","0.00681"
"35.57400","2.96466","0.00690"
"35.64000","2.97016","0.00689"
"35.70600","2.97567","0.00714"
"35.77200","2.98117","0.00678"
"35.83800","2.98673","0.00666"
"35.90400","2.99217","0.00680"
"35.97000","2.99773","0.00687"
"36.03600","3.00317","0.00681"
"36.10200","3.00867","0.00678"
"36.16800","3.01411","0.00683"
"36.23400","3.01967","0.00692"
"36.30000","3.02511","0.00675"
"36.36600","3.03067","0.00653"
"36.43200","3.03611","0.00671"
"36.49800","3.04173","0.00685"
"36.56400","3.04717","0.00621"
"36.63000","3.05267","0.00693"
"36.69600","3.05812","0.00711"
"36.76200","3.06362","0.00700"
"36.82800","3.06912","0.00683"
"36.89400","3.07468","0.00661"
"36.96000","3.08018","0.00704"
"37.02600","3.08568","0.00685"
"37.09200","3.09118","0.00694"
"37.15800","3.09668","0.00682"
"37.22400","3.10218","0.00709"
"37.29000","3.10762","0.00660"
"37.35600","3.11318","0.00687"
"37.42200","3.11868","0.00691"
"37.48800","3.12424","0.00685"
"37.55400","3.12962","0.00727"
"37.62000","3.13512","0.00680"
"37.68600","3.14068","0.00687"
"37.75200","3.14618","0.00698"
"37.81800","3.15163","0.00701"
"37.88400","3.15713","0.00658"
"37.95000","3.16269","0.00678"
"38.01600","3.16813","0.00734"
"38.08200","3.17369","0.00670"
"38.14800","3.17913","0.00686"
"38.21400","3.18469","0.00703"
"38.28000","3.19007","0.00655"
"38.34600","3.19563","0.00699"
"38.41200","3.20107","0.00670"
"38.47800","3.20663","0.00713"
"38.54400","3.21219","0.00680"
"38.61000","3.21763","0.00722"
"38.67600","3.22313","0.00693"
"38.74200","3.22858","0.00727"
"38.80800","3.23414","0.00657"
"38.87400","3.23958","0.00698"
"38.94000","3.24514","0.00705"
"39.00600","3.25064","0.00700"
"39.07200","3.25620","0.00693"
"39.13800","3.26170","0.00643"
"39.20400","3.26714","0.00689"
"39.27000","3.27264","0.00687"
"39.33600","3.27814","0.00700"
"39.40200","3.28364","0.00711"
"39.46800","3.28914","0.00688"
"39.53400","3.29464","0.00716"
"39.60000","3.30020","0.00692"
"39.66600","3.30564","0.00691"
"39.73200","3.31120","0.00689"
"39.79800","3.31664","0.00706"
"39.86400","3.32215","0.00671"
"39.93000","3.32759","0.00654"
"39.99600","3.33315","0.00720"
"40.06200","3.33865","0.00683"
"40.12800","3.34421","0.00681"
"40.19400","3.34965","0.00738"
"40.26000","3.35521","0.00721"
"40.32600","3.36065","0.00683"
"40.39200","3.36621","0.00684"
"40.45800","3.37159","0.00703"
"40.52400","3.37715","0.00689"
"40.59000","3.38265","0.00731"
"40.65600","3.38821","0.00698"
"40.72200","3.39365","0.00704"
"40.78800","3.39915","0.00684"
"40.85400","3.40460","0.00711"
"40.92000","3.41016","0.00694"
"40.98600","3.41560","0.00703"
"41.05200","3.42104","0.00701"
"41.11800","3.42666","0.00691"
"41.18400","3.43216","0.00669"
"41.25000","3.43772","0.00702"
"41.31600","3.44316","0.00676"
"41.38200","3.44872","0.00682"
"41.44800","3.45416","0.00698"
"41.51400","3.45966","0.00724"
"41.58000","3.46510","0.00690"
"41.64600","3.47066","0.00708"
"41.71200","3.47616","0.00689"
"41.77800","3.48172","0.00685"
"41.84400","3.48722","0.00725"
"41.91000","3.49267","0.00688"
"41.97600","3.49817","0.00699"
"42.04200","3.50361","0.00696"
"42.10800","3.50917","0.00709"
"42.17400","3.51461","0.00688"
"42.24000","3.52017","0.00742"
"42.30600","3.52567","0.00727"
"42.37200","3.53123","0.00715"
"42.43800","3.53667","0.00708"
"42.50400","3.54217","0.00705"
"42.57000","3.54767","0.00699"
"42.63600","3.55311","0.00721"
"42.70200","3.55867","0.00736"
"42.76800","3.56411","0.00717"
"42.83400","3.56967","0.00707"
"42.90000","3.57518","0.00715"
"42.96600","3.58068","0.00707"
"43.03200","3.58612","0.00691"
"43.09800","3.59162","0.00744"
"43.16400","3.59712","0.00649"
"43.23000","3.60262","0.00685"
"43.29600","3.60812","0.00720"
"43.36200","3.61362","0.00710"
"43.42800","3.61912","0.00692"
"43.49400","3.62468","0.00755"
"43.56000","3.63018","0.00699"
"43.62600","3.63562","0.00752"
"43.69200","3.64112","0.00698"
"43.75800","3.64662","0.00698"
"43.82400","3.65212","0.00711"
"43.89000","3.65762","0.00700"
"43.95600","3.66319","0.00720"
"44.02200","3.66869","0.00742"
"44.08800","3.67419","0.00696"
"44.15400","3.67963","0.00718"
"44.22000","3.68513","0.00681"
"44.28600","3.69063","0.00713"
"44.35200","3.69613","0.00721"
"44.41800","3.70163","0.00703"
"44.48400","3.70713","0.00706"
"44.55000","3.71269","0.00726"
"44.61600","3.71819","0.00730"
"44.68200","3.72369","0.00736"
"44.74800","3.72913","0.00737"
"44.81400","3.73463","0.00682"
"44.88000","3.74013","0.00710"
"44.94600","3.74569","0.00728"
"45.01200","3.75114","0.00756"
"45.07800","3.75670","0.00717"
"45.14400","3.76220","0.00715"
"45.21000","3.76764","0.00718"
"45.27600","3.77314","0.00734"
"45.34200","3.77858","0.00724"
"45.40800","3.78420","0.00722"
"45.47400","3.78964","0.00703"
"45.54000","3.79520","0.00760"
"45.60600","3.80058","0.00731"
"45.67200","3.80614","0.00713"
"45.73800","3.81164","0.00713"
"45.80400","3.81714","0.00698"
"45.87000","3.82258","0.00749"
"45.93600","3.82808","0.00724"
"46.00200","3.83359","0.00722"
"46.06800","3.83915","0.00689"
"46.13400","3.84471","0.00718"
"46.20000","3.85015","0.00736"
"46.26600","3.85565","0.00718"
"46.33200","3.86109","0.00728"
"46.39800","3.86665","0.00684"
"46.46400","3.87209","0.00732"
"46.53000","3.87765","0.00737"
"46.59600","3.88315","0.00750"
"46.66200","3.88865","0.00715"
"46.72800","3.89415","0.00707"
"46.79400","3.89965","0.00713"
"46.86000","3.90515","0.00763"
"46.92600","3.91065","0.00756"
"46.99200","3.91609","0.00668"
"47.05800","3.92165","0.00748"
"47.12400","3.92716","0.00739"
"47.19000","3.93266","0.00686"
"47.25600","3.93816","0.00737"
"47.32200","3.94366","0.00722"
"47.38800","3.94916","0.00733"
"47.45400","3.95466","0.00715"
"47.52000","3.96010","0.00710"
"47.58600","3.96560","0.00718"
"47.65200","3.97116","0.00737"
"47.71800","3.97666","0.00738"
"47.78400","3.98216","0.00714"
"47.85000","3.98766","0.00758"
"47.91600","3.99310","0.00717"
"47.98200","3.99866","0.00720"
"48.04800","4.00411","0.00738"
"48.11400","4.00967","0.00726"
"48.18000","4.01517","0.00728"
"48.24600","4.02067","0.00733"
"48.31200","4.02617","0.00721"
"48.37800","4.03167","0.00730"
"48.44400","4.03717","0.00738"
"48.51000","4.04261","0.00745"
"48.57600","4.04817","0.00738"
"48.64200","4.05361","0.00740"
"48.70800","4.05917","0.00734"
"48.77400","4.06467","0.00738"
"48.84000","4.07017","0.00754"
"48.90600","4.07567","0.00751"
"48.97200","4.08117","0.00769"
"49.03800","4.08667","0.00730"
"49.10400","4.09211","0.00718"
"49.17000","4.09762","0.00777"
"49.23600","4.10312","0.00758"
"49.30200","4.10868","0.00734"
"49.36800","4.11412","0.00760"
"49.43400","4.11968","0.00748"
"49.50000","4.12512","0.00740"
"49.56600","4.13068","0.00768"
"49.63200","4.13612","0.00726"
"49.69800","4.14168","0.00751"
"49.76400","4.14712","0.00719"
"49.83000","4.15268","0.00722"
"49.89600","4.15818","0.00730"
"49.96200","4.16368","0.00742"
"50.02800","4.16918","0.00732"
"50.09400","4.17462","0.00763"
"50.16000","4.18013","0.00739"
"50.22600","4.18563","0.00737"
"50.29200","4.19119","0.00740"
"50.35800","4.19669","0.00735"
"50.42400","4.20225","0.00755"
"50.49000","4.20769","0.00780"
"50.55600","4.21319","0.00751"
"50.62200","4.21863","0.00784"
"50.68800","4.22413","0.00731"
"50.75400","4.22957","0.00733"
"50.82000","4.23513","0.00763"
"50.88600","4.24069","0.00716"
"50.95200","4.24619","0.00751"
"51.01800","4.25169","0.00736"
"51.08400","4.25713","0.00738"
"51.15000","4.26269","0.00734"
"51.21600","4.26814","0.00723"
"51.28200","4.27364","0.00734"
"51.34800","4.27914","0.00731"
"51.41400","4.28470","0.00766"
"51.48000","4.29014","0.00751"
"51.54600","4.29570","0.00742"
"51.61200","4.30120","0.00729"
"51.67800","4.30664","0.00753"
"51.74400","4.31214","0.00723"
"51.81000","4.31758","0.00768"
"51.87600","4.32314","0.00746"
"51.94200","4.32864","0.00760"
"52.00800","4.33420","0.00784"
"52.07400","4.33970","0.00734"
"52.14000","4.34520","0.00723"
"52.20600","4.35065","0.00758"
"52.27200","4.35615","0.00742"
"52.33800","4.36165","0.00693"
"52.40400","4.36715","0.00761"
"52.47000","4.37265","0.00732"
"52.53600","4.37815","0.00742"
"52.60200","4.38365","0.00702"
"52.66800","4.38921","0.00740"
"52.73400","4.39465","0.00750"
"52.80000","4.40015","0.00766"
"52.86600","4.40565","0.00756"
"52.93200","4.41115","0.00741"
"52.99800","4.41665","0.00754"
"53.06400","4.42215","0.00711"
"53.13000","4.42771","0.00729"
"53.19600","4.43321","0.00761"
"53.26200","4.43866","0.00724"
"53.32800","4.44410","0.00725"
"53.39400","4.44960","0.00758"
"53.46000","4.45516","0.00746"
"53.52600","4.46060","0.00758"
"53.59200","4.46616","0.00767"
"53.65800","4.47160","0.00744"
"53.72400","4.47716","0.00725"
"53.79000","4.48260","0.00769"
"53.85600","4.48816","0.00763"
"53.92200","4.49360","0.00747"
"53.98800","4.49910","0.00766"
"54.05400","4.50460","0.00762"
"54.12000","4.51016","0.00743"
"54.18600","4.51560","0.00767"
"54.25200","4.52110","0.00764"
"54.31800","4.52667","0.00767"
"54.38400","4.53217","0.00740"
"54.45000","4.53761","0.00743"
"54.51600","4.54311","0.00744"
"54.58200","4.54867","0.00763"
"54.64800","4.55417","0.00747"
"54.71400","4.55967","0.00721"
"54.78000","4.56517","0.00738"
"54.84600","4.57067","0.00773"
"54.91200","4.57617","0.00760"
"54.97800","4.58167","0.00757"
"55.04400","4.58711","0.00767"
"55.11000","4.59267","0.00758"
"55.17600","4.59817","0.00791"
"55.24200","4.60367","0.00744"
"55.30800","4.60918","0.00771"
"55.37400","4.61468","0.00762"
"55.44000","4.62018","0.00774"
"55.50600","4.62562","0.00757"
"55.57200","4.63112","0.00740"
"55.63800","4.63662","0.00748"
"55.70400","4.64218","0.00752"
"55.77000","4.64768","0.00796"
"55.83600","4.65312","0.00735"
"55.90200","4.65868","0.00730"
"55.96800","4.66412","0.00759"
"56.03400","4.66962","0.00734"
"56.10000","4.67506","0.00749"
"56.16600","4.68068","0.00755"
"56.23200","4.68618","0.00728"
"56.29800","4.69168","0.00775"
"56.36400","4.69719","0.00708"
"56.43000","4.70263","0.00737"
"56.49600","4.70819","0.00776"
"56.56200","4.71363","0.00757"
"56.62800","4.71913","0.00739"
"56.69400","4.72463","0.00760"
"56.76000","4.73013","0.00754"
"56.82600","4.73563","0.00720"
"56.89200","4.74113","0.00747"
"56.95800","4.74663","0.00790"
"57.02400","4.75219","0.00752"
"57.09000","4.75763","0.00769"
"57.15600","4.76307","0.00744"
"57.22200","4.76857","0.00750"
"57.28800","4.77419","0.00750"
"57.35400","4.77970","0.00778"
"57.42000","4.78520","0.00767"
"57.48600","4.79070","0.00730"
"57.55200","4.79614","0.00782"
"57.61800","4.80170","0.00748"
"57.68400","4.80714","0.00759"
"57.75000","4.81270","0.00777"
"57.81600","4.81814","0.00797"
"57.88200","4.82376","0.00712"
"57.94800","4.82914","0.00701"
"58.01400","4.83470","0.00750"
"58.08000","4.84014","0.00744"
"58.14600","4.84564","0.00763"
"58.21200","4.85108","0.00728"
"58.27800","4.85658","0.00749"
"58.34400","4.86214","0.00747"
"58.41000","4.86765","0.00760"
"58.47600","4.87315","0.00740"
"58.54200","4.87865","0.00778"
"58.60800","4.88421","0.00745"
"58.67400","4.88965","0.00767"
"58.74000","4.89515","0.00754"
"58.80600","4.90065","0.00782"
"58.87200","4.90615","0.00769"
"58.93800","4.91165","0.00754"
"59.00400","4.91715","0.00733"
"59.07000","4.92265","0.00753"
"59.13600","4.92821","0.00786"
"59.20200","4.93371","0.00762"
"59.26800","4.93915","0.00731"
"59.33400","4.94459","0.00767"
"59.40000","4.95010","0.00736"
"59.46600","4.95572","0.00745"
"59.53200","4.96116","0.00799"
"59.59800","4.96672","0.00742"
"59.66400","4.97216","0.00766"
"59.73000","4.97766","0.00752"
"59.79600","4.98316","0.00762"
"59.86200","4.98866","0.00751"
"59.92800","4.99410","0.00772"
"59.99400","4.99966","0.00753"
"60.06000","5.00516","0.00789"
"60.12600","5.01072","0.00767"
"60.19200","5.01616","0.00775"
"60.25800","5.02166","0.00775"
"60.32400","5.02710","0.00776"
"60.39000","5.03266","0.00790"
"60.45600","5.03811","0.00765"
"60.52200","5.04367","0.00738"
"60.58800","5.04917","0.00791"
"60.65400","5.05467","0.00759"
"60.72000","5.06017","0.00740"
"60.78600","5.06567","0.00765"
"60.85200","5.07117","0.00787"
"60.91800","5.07667","0.00755"
"60.98400","5.08211","0.00770"
"61.05000","5.08767","0.00790"
"61.11600","5.09317","0.00787"
"61.18200","5.09873","0.00745"
"61.24800","5.10417","0.00792"
"61.31400","5.10967","0.00786"
"61.38000","5.11517","0.00757"
"61.44600","5.12067","0.00768"
"61.51200","5.12612","0.00730"
"61.57800","5.13162","0.00780"
"61.64400","5.13718","0.00773"
"61.71000","5.14262","0.00761"
"61.77600","5.14824","0.00772"
"61.84200","5.15362","0.00762"
"61.90800","5.15918","0.00785"
"61.97400","5.16456","0.00765"
"62.04000","5.17018","0.00769"
"62.10600","5.17562","0.00782"
"62.17200","5.18118","0.00770"
"62.23800","5.18668","0.00809"
"62.30400","5.19218","0.00751"
"62.37000","5.19768","0.00754"
"62.43600","5.20318","0.00753"
"62.50200","5.20862","0.00787"
"62.56800","5.21413","0.00760"
"62.63400","5.21963","0.00749"
"62.70000","5.22519","0.00794"
"62.76600","5.23069","0.00765"
"62.83200","5.23613","0.00758"
"62.89800","5.24169","0.00762"
"62.96400","5.24719","0.00785"
"63.03000","5.25269","0.00752"
"63.09600","5.25813","0.00769"
"63.16200","5.26363","0.00813"
"63.22800","5.26919","0.00771"
"63.29400","5.27469","0.00748"
"63.36000","5.28019","0.00792"
"63.42600","5.28563","0.00779"
"63.49200","5.29119","0.00795"
"63.55800","5.29664","0.00736"
"63.62400","5.30214","0.00772"
"63.69000","5.30764","0.00787"
"63.75600","5.31314","0.00775"
"63.82200","5.31864","0.00774"
"63.88800","5.32414","0.00762"
"63.95400","5.32970","0.00800"
"64.02000","5.33514","0.00802"
"64.08600","5.34064","0.00751"
"64.15200","5.34608","0.00765"
"64.21800","5.35164","0.00797"
"64.28400","5.35714","0.00769"
"64.35000","5.36270","0.00759"
"64.41600","5.36814","0.00730"
"64.48200","5.37370","0.00776"
"64.54800","5.37915","0.00774"
"64.61400","5.38465","0.00735"
"64.68000","5.39009","0.00785"
"64.74600","5.39565","0.00755"
"64.81200","5.40115","0.00760"
"64.87800","5.40665","0.00756"
"64.94400","5.41215","0.00774"
"65.01000","5.41765","0.00736"
"65.07600","5.42315","0.00783"
"65.14200","5.42859","0.00768"
"65.20800","5.43415","0.00792"
"65.27400","5.43959","0.00790"
"65.34000","5.44515","0.00760"
"65.40600","5.45065","0.00764"
"65.47200","5.45615","0.00767"
"65.53800","5.46165","0.00764"
"65.60400","5.46715","0.00794"
"65.67000","5.47266","0.00788"
"65.73600","5.47810","0.00765"
"65.80200","5.48360","0.00779"
"65.86800","5.48916","0.00756"
"65.93400","5.49472","0.00765"
"66.00000","5.50016","0.00762"
"66.06600","5.50572","0.00768"
"66.13200","5.51116","0.00757"
"66.19800","5.51666","0.00772"
"66.26400","5.52204","0.00780"
"66.33000","5.52760","0.00741"
"66.39600","5.53316","0.00803"
"66.46200","5.53872","0.00805"
"66.52800","5.54422","0.00764"
"66.59400","5.54966","0.00771"
"66.66000","5.55516","0.00781"
"66.72600","5.56061","0.00753"
"66.79200","5.56617","0.00757"
"66.85800","5.57155","0.00764"
"66.92400","5.57717","0.00784"
"66.99000","5.58261","0.00763"
"67.05600","5.58817","0.00791"
"67.12200","5.59361","0.00772"
"67.18800","5.59917","0.00784"
"67.25400","5.60467","0.00767"
"67.32000","5.61011","0.00779"
"67.38600","5.61561","0.00788"
"67.45200","5.62111","0.00772"
"67.51800","5.62667","0.00757"
"67.58400","5.63217","0.00815"
"67.65000","5.63767","0.00762"
"67.71600","5.64318","0.00775"
"67.78200","5.64868","0.00765"
"67.84800","5.65418","0.00770"
"67.91400","5.65956","0.00773"
"67.98000","5.66512","0.00786"
"68.04600","5.67068","0.00753"
"68.11200","5.67618","0.00781"
"68.17800","5.68168","0.00786"
"68.24400","5.68718","0.00766"
"68.31000","5.69268","0.00807"
"68.37600","5.69818","0.00786"
"68.44200","5.70362","0.00770"
"68.50800","5.70912","0.00784"
"68.57400","5.71462","0.00760"
"68.64000","5.72018","0.00777"
"68.70600","5.72569","0.00769"
"68.77200","5.73118","0.00754"
"68.83800","5.73663","0.00754"
"68.90400","5.74213","0.00765"
"68.97000","5.74763","0.00770"
"69.03600","5.75307","0.00776"
"69.10200","5.75863","0.00763"
"69.16800","5.76413","0.00754"
"69.23400","5.76969","0.00773"
"69.30000","5.77513","0.00719"
"69.36600","5.78069","0.00782"
"69.43200","5.78613","0.00748"
"69.49800","5.79163","0.00765"
"69.56400","5.79707","0.00759"
"69.63000","5.80269","0.00713"
"69.69600","5.80819","0.00788"
"69.76200","5.81369","0.00764"
"69.82800","5.81914","0.00786"
"69.89400","5.82470","0.00729"
"69.96000","5.83014","0.00771"
"70.02600","5.83564","0.00761"
"70.09200","5.84114","0.00760"
"70.15800","5.84664","0.00770"
"70.22400","5.85214","0.00783"
"70.29000","5.85770","0.00770"
"70.35600","5.86320","0.00763"
"70.42200","5.86870","0.00776"
"70.48800","5.87420","0.00799"
"70.55400","5.87964","0.00770"
"70.62000","5.88508","0.00757"
"70.68600","5.89064","0.00802"
"70.75200","5.89614","0.00766"
"70.81800","5.90170","0.00746"
"70.88400","5.90715","0.00746"
"70.95000","5.91271","0.00759"
"71.01600","5.91815","0.00763"
"71.08200","5.92359","0.00783"
"71.14800","5.92909","0.00784"
"71.21400","5.93459","0.00771"
"71.28000","5.94015","0.00758"
"71.34600","5.94565","0.00756"
"71.41200","5.95115","0.00751"
"71.47800","5.95665","0.00744"
"71.54400","5.96215","0.00770"
"71.61000","5.96765","0.00789"
"71.67600","5.97309","0.00771"
"71.74200","5.97859","0.00757"
"71.80800","5.98416","0.00772"
"71.87400","5.98966","0.00768"
"71.94000","5.99516","0.00806"
"72.00600","6.00072","0.00758"
"72.07200","6.00616","0.00749"
"72.13800","6.01166","0.00757"
"72.20400","6.01716","0.00747"
"72.27000","6.02266","0.00740"
"72.33600","6.02816","0.00751"
"72.40200","6.03366","0.00750"
"72.46800","6.03916","0.00740"
"72.53400","6.04466","0.00769"
"72.60000","6.05016","0.00788"
"72.66600","6.05572","0.00740"
"72.73200","6.06110","0.00763"
"72.79800","6.06666","0.00800"
"72.86400","6.07211","0.00769"
"72.93000","6.07767","0.00770"
"72.99600","6.08317","0.00781"
"73.06200","6.08867","0.00758"
"73.12800","6.09417","0.00774"
"73.19400","6.09961","0.00774"
"73.26000","6.10517","0.00760"
"73.32600","6.11061","0.00748"
"73.39200","6.11611","0.00800"
"73.45800","6.12167","0.00764"
"73.52400","6.12723","0.00778"
"73.59000","6.13267","0.00784"
"73.65600","6.13817","0.00768"
"73.72200","6.14361","0.00804"
"73.78800","6.14917","0.00779"
"73.85400","6.15461","0.00752"
"73.92000","6.16012","0.00783"
"73.98600","6.16562","0.00782"
"74.05200","6.17112","0.00774"
"74.11800","6.17668","0.00723"
"74.18400","6.18218","0.00746"
"74.25000","6.18768","0.00779"
"74.31600","6.19312","0.00754"
"74.38200","6.19862","0.00787"
"74.44800","6.20412","0.00768"
"74.51400","6.20968","0.00749"
"74.58000","6.21518","0.00746"
"74.64600","6.22068","0.00737"
"74.71200","6.22612","0.00746"
"74.77800","6.23162","0.00741"
"74.84400","6.23718","0.00776"
"74.91000","6.24262","0.00766"
"74.97600","6.24813","0.00762"
"75.04200","6.25363","0.00738"
"75.10800","6.25919","0.00759"
"75.17400","6.26469","0.00733"
"75.24000","6.27019","0.00787"
"75.30600","6.27569","0.00770"
"75.37200","6.28113","0.00777"
"75.43800","6.28663","0.00742"
"75.50400","6.29213","0.00751"
"75.57000","6.29763","0.00784"
"75.63600","6.30319","0.00772"
"75.70200","6.30863","0.00747"
"75.76800","6.31419","0.00777"
"75.83400","6.31969","0.00759"
"75.90000","6.32514","0.00764"
"75.96600","6.33058","0.00772"
"76.03200","6.33608","0.00766"
"76.09800","6.34164","0.00810"
"76.16400","6.34720","0.00771"
"76.23000","6.35270","0.00791"
"76.29600","6.35814","0.00779"
"76.36200","6.36364","0.00758"
"76.42800","6.36914","0.00802"
"76.49400","6.37464","0.00764"
"76.56000","6.38014","0.00778"
"76.62600","6.38558","0.00748"
"76.69200","6.39120","0.00760"
"76.75800","6.39664","0.00741"
"76.82400","6.40220","0.00730"
"76.89000","6.40770","0.00798"
"76.95600","6.41315","0.00746"
"77.02200","6.41859","0.00788"
"77.08800","6.42415","0.00738"
"77.15400","6.42965","0.00779"
"77.22000","6.43515","0.00759"
"77.28600","6.44071","0.00765"
"77.35200","6.44615","0.00776"
"77.41800","6.45165","0.00762"
"77.48400","6.45709","0.00774"
"77.55000","6.46265","0.00745"
"77.61600","6.46809","0.00809"
"77.68200","6.47365","0.00778"
"77.74800","6.47909","0.00786"
"77.81400","6.48471","0.00816"
"77.88000","6.49015","0.00762"
"77.94600","6.49565","0.00750"
"78.01200","6.50116","0.00764"
"78.07800","6.50660","0.00812"
"78.14400","6.51210","0.00753"
"78.21000","6.51760","0.00763"
"78.27600","6.52316","0.00778"
"78.34200","6.52872","0.00779"
"78.40800","6.53422","0.00778"
"78.47400","6.53966","0.00749"
"78.54000","6.54522","0.00788"
"78.60600","6.55066","0.00756"
"78.67200","6.55616","0.00775"
"78.73800","6.56160","0.00778"
"78.80400","6.56710","0.00781"
"78.87000","6.57266","0.00730"
"78.93600","6.57816","0.00759"
"79.00200","6.58366","0.00784"
"79.06800","6.58917","0.00783"
"79.13400","6.59467","0.00757"
"79.20000","6.60011","0.00765"
"79.26600","6.60561","0.00773"
"79.33200","6.61111","0.00767"
"79.39800","6.61661","0.00767"
"79.46400","6.62211","0.00770"
"79.53000","6.62767","0.00777"
"79.59600","6.63317","0.00765"
"79.66200","6.63861","0.00786"
"79.72800","6.64411","0.00769"
"79.79400","6.64955","0.00778"
"79.86000","6.65517","0.00802"
"79.92600","6.66061","0.00776"
"79.99200","6.66623","0.00758"
"80.05800","6.67167","0.00732"
"80.12400","6.67718","0.00773"
"80.19000","6.68262","0.00758"
"80.25600","6.68818","0.00786"
"80.32200","6.69362","0.00770"
"80.38800","6.69912","0.00751"
"80.45400","6.70468","0.00772"
"80.52000","6.71018","0.00775"
"80.58600","6.71562","0.00778"
"80.65200","6.72118","0.00782"
"80.71800","6.72668","0.00746"
"80.78400","6.73218","0.00776"
"80.85000","6.73762","0.00811"
"80.91600","6.74318","0.00787"
"80.98200","6.74868","0.00769"
"81.04800","6.75424","0.00814"
"81.11400","6.75969","0.00768"
"81.18000","6.76519","0.00733"
"81.24600","6.77069","0.00765"
"81.31200","6.77613","0.00754"
"81.37800","6.78163","0.00750"
"81.44400","6.78713","0.00811"
"81.51000","6.79263","0.00779"
"81.57600","6.79825","0.00760"
"81.64200","6.80363","0.00773"
"81.70800","6.80919","0.00802"
"81.77400","6.81463","0.00770"
"81.84000","6.82019","0.00726"
"81.90600","6.82563","0.00777"
"81.97200","6.83113","0.00798"
"82.03800","6.83663","0.00770"
"82.10400","6.84219","0.00761"
"82.17000","6.84770","0.00751"
"82.23600","6.85314","0.00746"
"82.30200","6.85864","0.00757"
"82.36800","6.86408","0.00778"
"82.43400","6.86970","0.00794"
"82.50000","6.87508","0.00773"
"82.56600","6.88064","0.00757"
"82.63200","6.88614","0.00781"
"82.69800","6.89170","0.00781"
"82.76400","6.89720","0.00767"
"82.83000","6.90270","0.00756"
"82.89600","6.90814","0.00796"
"82.96200","6.91364","0.00791"
"83.02800","6.91914","0.00772"
"83.09400","6.92464","0.00771"
"83.16000","6.93015","0.00773"
"83.22600","6.93565","0.00779"
"83.29200","6.94115","0.00765"
"83.35800","6.94671","0.00769"
"83.42400","6.95215","0.00771"
"83.49000","6.95765","0.00746"
"83.55600","6.96309","0.00771"
"83.62200","6.96865","0.00760"
"83.68800","6.97415","0.00778"
"83.75400","6.97965","0.00797"
"83.82000","6.98515","0.00785"
"83.88600","6.99065","0.00770"
"83.95200","6.99609","0.00769"
"84.01800","7.00165","0.00764"
"84.08400","7.00703","0.00803"
"84.15000","7.01265","0.00787"
"84.21600","7.01816","0.00795"
"84.28200","7.02372","0.00762"
"84.34800","7.02916","0.00773"
"84.41400","7.03472","0.00747"
"84.48000","7.04016","0.00785"
"84.54600","7.04560","0.00765"
"84.61200","7.05110","0.00806"
"84.67800","7.05660","0.00794"
"84.74400","7.06216","0.00774"
"84.81000","7.06766","0.00751"
"84.87600","7.07322","0.00773"
"84.94200","7.07866","0.00764"
"85.00800","7.08416","0.00778"
"85.07400","7.08960","0.00798"
"85.14000","7.09510","0.00776"
"85.20600","7.10061","0.00779"
"85.27200","7.10617","0.00772"
"85.33800","7.11173","0.00791"
"85.40400","7.11717","0.00756"
"85.47000","7.12267","0.00774"
"85.53600","7.12811","0.00771"
"85.60200","7.13367","0.00753"
"85.66800","7.13911","0.00771"
"85.73400","7.14467","0.00796"
"85.80000","7.15011","0.00777"
"85.86600","7.15567","0.00783"
"85.93200","7.16117","0.00777"
"85.99800","7.16673","0.00809"
"86.06400","7.17217","0.00777"
"86.13000","7.17767","0.00797"
"86.19600","7.18311","0.00791"
"86.26200","7.18856","0.00794"
"86.32800","7.19412","0.00793"
"86.39400","7.19962","0.00824"
"86.46000","7.20518","0.00793"
"86.52600","7.21062","0.00812"
"86.59200","7.21618","0.00785"
"86.65800","7.22162","0.00792"
"86.72400","7.22718","0.00796"
"86.79000","7.23262","0.00736"
"86.85600","7.23812","0.00805"
"86.92200","7.24362","0.00750"
"86.98800","7.24918","0.00819"
"87.05400","7.25468","0.00799"
"87.12000","7.26018","0.00783"
"87.18600","7.26562","0.00776"
"87.25200","7.27112","0.00806"
"87.31800","7.27663","0.00767"
"87.38400","7.28213","0.00781"
"87.45000","7.28763","0.00786"
"87.51600","7.29313","0.00777"
"87.58200","7.29869","0.00791"
"87.64800","7.30419","0.00777"
"87.71400","7.30969","0.00809"
"87.78000","7.31513","0.00818"
"87.84600","7.32063","0.00779"
"87.91200","7.32613","0.00776"
"87.97800","7.33169","0.00791"
"88.04400","7.33713","0.00786"
"88.11000","7.34269","0.00796"
"88.17600","7.34819","0.00798"
"88.24200","7.35369","0.00820"
"88.30800","7.35914","0.00759"
"88.37400","7.36464","0.00751"
"88.44000","7.37014","0.00782"
"88.50600","7.37570","0.00807"
"88.57200","7.38120","0.00783"
"88.63800","7.38664","0.00811"
"88.70400","7.39220","0.00826"
"88.77000","7.39770","0.00776"
"88.83600","7.40320","0.00803"
"88.90200","7.40864","0.00764"
"88.96800","7.41414","0.00739"
"89.03400","7.41964","0.00762"
"89.10000","7.42514","0.00740"
"89.16600","7.43070","0.00738"
"89.23200","7.43614","0.00815"
"89.29800","7.44164","0.00792"
"89.36400","7.44714","0.00761"
"89.43000","7.45265","0.00774"
"89.49600","7.45809","0.00793"
"89.56200","7.46365","0.00800"
"89.62800","7.46921","0.00768"
"89.69400","7.47465","0.00805"
"89.76000","7.48015","0.00759"
"89.82600","7.48565","0.00778"
"89.89200","7.49121","0.00788"
"89.95800","7.49659","0.00790"
"90.01200","7.50114","0.00784"