File: old/analysis_20190400_old/old/End.date_24BG_95_.csv
"","V1","V2","V3"
"1","","End.date","X12.21.2016"
"2","Specimen label","24BG_95",""
"3","Maximum Load","0.00842","N"
"4","Time","Extension","Load"
"5","(s)","(mm)","(N)"
"6","0.00000","-0.00006","0.00061"
"18","0.07200","0.00197","0.00101"
"30","0.14400","0.00801","0.00135"
"42","0.21600","0.01596","0.00104"
"54","0.28800","0.02338","0.00099"
"66","0.36000","0.03007","0.00131"
"78","0.43200","0.03629","0.00139"
"90","0.50400","0.04221","0.00146"
"102","0.57600","0.04819","0.00173"
"114","0.64800","0.05417","0.00169"
"126","0.72000","0.06015","0.00134"
"138","0.79200","0.06619","0.00141"
"150","0.86400","0.07223","0.00180"
"162","0.93600","0.07820","0.00209"
"174","1.00800","0.08418","0.00183"
"186","1.08000","0.09016","0.00187"
"198","1.15200","0.09614","0.00218"
"210","1.22400","0.10212","0.00173"
"222","1.29600","0.10816","0.00219"
"234","1.36800","0.11420","0.00214"
"246","1.44000","0.12018","0.00266"
"258","1.51200","0.12622","0.00217"
"270","1.58400","0.13219","0.00215"
"282","1.65600","0.13817","0.00261"
"294","1.72800","0.14415","0.00248"
"306","1.80000","0.15013","0.00257"
"318","1.87200","0.15617","0.00276"
"330","1.94400","0.16215","0.00240"
"342","2.01600","0.16819","0.00267"
"354","2.08800","0.17417","0.00258"
"366","2.16000","0.18015","0.00259"
"378","2.23200","0.18612","0.00267"
"390","2.30400","0.19204","0.00264"
"402","2.37600","0.19820","0.00283"
"414","2.44800","0.20418","0.00278"
"426","2.52000","0.21016","0.00284"
"438","2.59200","0.21614","0.00273"
"450","2.66400","0.22218","0.00259"
"462","2.73600","0.22816","0.00265"
"474","2.80800","0.23414","0.00323"
"486","2.88000","0.24011","0.00289"
"498","2.95200","0.24615","0.00269"
"510","3.02400","0.25219","0.00286"
"522","3.09600","0.25817","0.00320"
"534","3.16800","0.26415","0.00337"
"546","3.24000","0.27019","0.00333"
"558","3.31200","0.27617","0.00304"
"570","3.38400","0.28215","0.00332"
"582","3.45600","0.28819","0.00348"
"594","3.52800","0.29416","0.00321"
"606","3.60000","0.30014","0.00345"
"618","3.67200","0.30618","0.00307"
"630","3.74400","0.31216","0.00325"
"642","3.81600","0.31814","0.00332"
"654","3.88800","0.32412","0.00320"
"666","3.96000","0.33016","0.00371"
"678","4.03200","0.33614","0.00344"
"690","4.10400","0.34218","0.00345"
"702","4.17600","0.34815","0.00338"
"714","4.24800","0.35419","0.00324"
"726","4.32000","0.36017","0.00352"
"738","4.39200","0.36615","0.00335"
"750","4.46400","0.37207","0.00347"
"762","4.53600","0.37811","0.00349"
"774","4.60800","0.38415","0.00359"
"786","4.68000","0.39019","0.00336"
"798","4.75200","0.39617","0.00368"
"810","4.82400","0.40214","0.00411"
"822","4.89600","0.40812","0.00365"
"834","4.96800","0.41410","0.00366"
"846","5.04000","0.42014","0.00389"
"858","5.11200","0.42618","0.00470"
"870","5.18400","0.43216","0.00340"
"882","5.25600","0.43814","0.00322"
"894","5.32800","0.44418","0.00042"
"906","5.40000","0.45016","-0.00053"
"918","5.47200","0.45613","0.00527"
"930","5.54400","0.46211","0.00378"
"942","5.61600","0.46815","0.00317"
"954","5.68800","0.47419","0.00308"
"966","5.76000","0.48017","0.00328"
"978","5.83200","0.48615","0.00376"
"990","5.90400","0.49219","0.00430"
"1002","5.97600","0.49817","0.00441"
"1014","6.04800","0.50409","0.00407"
"1026","6.12000","0.51012","0.00358"
"1038","6.19200","0.51616","0.00309"
"1050","6.26400","0.52220","0.00323"
"1062","6.33600","0.52818","0.00411"
"1074","6.40800","0.53416","0.00439"
"1086","6.48000","0.54014","0.00383"
"1098","6.55200","0.54612","0.00338"
"1110","6.62400","0.55210","0.00365"
"1122","6.69600","0.55814","0.00376"
"1134","6.76800","0.56417","0.00357"
"1146","6.84000","0.57015","0.00409"
"1158","6.91200","0.57619","0.00394"
"1170","6.98400","0.58217","0.00367"
"1182","7.05600","0.58815","0.00372"
"1194","7.12800","0.59413","0.00361"
"1206","7.20000","0.60011","0.00400"
"1218","7.27200","0.60615","0.00365"
"1230","7.34400","0.61213","0.00383"
"1242","7.41600","0.61816","0.00376"
"1254","7.48800","0.62414","0.00385"
"1266","7.56000","0.63018","0.00378"
"1278","7.63200","0.63610","0.00416"
"1290","7.70400","0.64208","0.00404"
"1302","7.77600","0.64818","0.00371"
"1314","7.84800","0.65422","0.00352"
"1326","7.92000","0.66020","0.00410"
"1338","7.99200","0.66618","0.00376"
"1350","8.06400","0.67215","0.00386"
"1362","8.13600","0.67813","0.00412"
"1374","8.20800","0.68411","0.00419"
"1386","8.28000","0.69009","0.00458"
"1398","8.35200","0.69613","0.00388"
"1410","8.42400","0.70217","0.00404"
"1422","8.49600","0.70815","0.00381"
"1434","8.56800","0.71413","0.00406"
"1446","8.64000","0.72016","0.00404"
"1458","8.71200","0.72614","0.00399"
"1470","8.78400","0.73212","0.00415"
"1482","8.85600","0.73810","0.00462"
"1494","8.92800","0.74414","0.00427"
"1506","9.00000","0.75018","0.00408"
"1518","9.07200","0.75622","0.00450"
"1530","9.14400","0.76214","0.00408"
"1542","9.21600","0.76812","0.00457"
"1554","9.28800","0.77410","0.00440"
"1566","9.36000","0.78013","0.00429"
"1578","9.43200","0.78617","0.00431"
"1590","9.50400","0.79221","0.00451"
"1602","9.57600","0.79819","0.00475"
"1614","9.64800","0.80417","0.00453"
"1626","9.72000","0.81015","0.00437"
"1638","9.79200","0.81619","0.00443"
"1650","9.86400","0.82217","0.00456"
"1662","9.93600","0.82820","0.00426"
"1674","10.00800","0.83418","0.00479"
"1686","10.08000","0.84022","0.00462"
"1698","10.15200","0.84620","0.00451"
"1710","10.22400","0.85218","0.00466"
"1722","10.29600","0.85810","0.00436"
"1734","10.36800","0.86414","0.00466"
"1746","10.44000","0.87012","0.00467"
"1758","10.51200","0.87616","0.00437"
"1770","10.58400","0.88213","0.00446"
"1782","10.65600","0.88817","0.00460"
"1794","10.72800","0.89415","0.00494"
"1806","10.80000","0.90013","0.00426"
"1818","10.87200","0.90611","0.00509"
"1830","10.94400","0.91209","0.00475"
"1842","11.01600","0.91819","0.00449"
"1854","11.08800","0.92417","0.00497"
"1866","11.16000","0.93015","0.00507"
"1878","11.23200","0.93612","0.00499"
"1890","11.30400","0.94222","0.00482"
"1902","11.37600","0.94814","0.00486"
"1914","11.44800","0.95412","0.00481"
"1926","11.52000","0.96016","0.00461"
"1938","11.59200","0.96620","0.00502"
"1950","11.66400","0.97218","0.00507"
"1962","11.73600","0.97816","0.00489"
"1974","11.80800","0.98420","0.00508"
"1986","11.88000","0.99017","0.00539"
"1998","11.95200","0.99621","0.00480"
"2010","12.02400","1.00219","0.00465"
"2022","12.09600","1.00823","0.00471"
"2034","12.16800","1.01421","0.00487"
"2046","12.24000","1.02025","0.00484"
"2058","12.31200","1.02617","0.00540"
"2070","12.38400","1.03221","0.00491"
"2082","12.45600","1.03813","0.00512"
"2094","12.52800","1.04416","0.00530"
"2106","12.60000","1.05008","0.00457"
"2118","12.67200","1.05618","0.00508"
"2130","12.74400","1.06216","0.00473"
"2142","12.81600","1.06814","0.00500"
"2154","12.88800","1.07412","0.00498"
"2166","12.96000","1.08016","0.00483"
"2178","13.03200","1.08608","0.00522"
"2190","13.10400","1.09218","0.00562"
"2202","13.17600","1.09815","0.00543"
"2214","13.24800","1.10419","0.00525"
"2226","13.32000","1.11017","0.00554"
"2238","13.39200","1.11621","0.00544"
"2250","13.46400","1.12213","0.00539"
"2262","13.53600","1.12817","0.00532"
"2274","13.60800","1.13409","0.00524"
"2286","13.68000","1.14019","0.00523"
"2298","13.75200","1.14617","0.00500"
"2310","13.82400","1.15220","0.00513"
"2322","13.89600","1.15818","0.00489"
"2334","13.96800","1.16422","0.00504"
"2346","14.04000","1.17014","0.00498"
"2358","14.11200","1.17612","0.00526"
"2370","14.18400","1.18210","0.00508"
"2382","14.25600","1.18820","0.00511"
"2394","14.32800","1.19418","0.00514"
"2406","14.40000","1.20022","0.00525"
"2418","14.47200","1.20619","0.00510"
"2430","14.54400","1.21217","0.00491"
"2442","14.61600","1.21815","0.00533"
"2454","14.68800","1.22413","0.00502"
"2466","14.76000","1.23017","0.00518"
"2478","14.83200","1.23615","0.00516"
"2490","14.90400","1.24219","0.00499"
"2502","14.97600","1.24817","0.00508"
"2514","15.04800","1.25415","0.00535"
"2526","15.12000","1.26012","0.00534"
"2538","15.19200","1.26610","0.00532"
"2550","15.26400","1.27214","0.00524"
"2562","15.33600","1.27812","0.00552"
"2574","15.40800","1.28422","0.00528"
"2586","15.48000","1.29014","0.00508"
"2598","15.55200","1.29618","0.00551"
"2610","15.62400","1.30210","0.00531"
"2622","15.69600","1.30814","0.00518"
"2634","15.76800","1.31405","0.00559"
"2646","15.84000","1.32021","0.00539"
"2658","15.91200","1.32619","0.00545"
"2670","15.98400","1.33223","0.00534"
"2682","16.05600","1.33821","0.00528"
"2694","16.12800","1.34419","0.00530"
"2706","16.20000","1.35017","0.00537"
"2718","16.27200","1.35615","0.00526"
"2730","16.34400","1.36213","0.00543"
"2742","16.41600","1.36816","0.00533"
"2754","16.48800","1.37420","0.00513"
"2766","16.56000","1.38018","0.00538"
"2778","16.63200","1.38616","0.00568"
"2790","16.70400","1.39220","0.00539"
"2802","16.77600","1.39818","0.00539"
"2814","16.84800","1.40416","0.00534"
"2826","16.92000","1.41014","0.00542"
"2838","16.99200","1.41623","0.00527"
"2850","17.06400","1.42215","0.00560"
"2862","17.13600","1.42825","0.00532"
"2874","17.20800","1.43411","0.00556"
"2886","17.28000","1.44015","0.00574"
"2898","17.35200","1.44607","0.00569"
"2910","17.42400","1.45217","0.00580"
"2922","17.49600","1.45815","0.00554"
"2934","17.56800","1.46419","0.00537"
"2946","17.64000","1.47016","0.00526"
"2958","17.71200","1.47620","0.00569"
"2970","17.78400","1.48212","0.00598"
"2982","17.85600","1.48816","0.00548"
"2994","17.92800","1.49408","0.00582"
"3006","18.00000","1.50012","0.00546"
"3018","18.07200","1.50616","0.00577"
"3030","18.14400","1.51220","0.00588"
"3042","18.21600","1.51818","0.00573"
"3054","18.28800","1.52415","0.00541"
"3066","18.36000","1.53019","0.00565"
"3078","18.43200","1.53611","0.00591"
"3090","18.50400","1.54215","0.00548"
"3102","18.57600","1.54813","0.00545"
"3114","18.64800","1.55417","0.00542"
"3126","18.72000","1.56015","0.00543"
"3138","18.79200","1.56619","0.00542"
"3150","18.86400","1.57217","0.00536"
"3162","18.93600","1.57814","0.00531"
"3174","19.00800","1.58412","0.00552"
"3186","19.08000","1.59016","0.00572"
"3198","19.15200","1.59620","0.00585"
"3210","19.22400","1.60218","0.00535"
"3222","19.29600","1.60822","0.00581"
"3234","19.36800","1.61414","0.00567"
"3246","19.44000","1.62018","0.00546"
"3258","19.51200","1.62610","0.00568"
"3270","19.58400","1.63219","0.00528"
"3282","19.65600","1.63817","0.00583"
"3294","19.72800","1.64421","0.00565"
"3306","19.80000","1.65013","0.00586"
"3318","19.87200","1.65617","0.00522"
"3330","19.94400","1.66215","0.00569"
"3342","20.01600","1.66813","0.00562"
"3354","20.08800","1.67405","0.00586"
"3366","20.16000","1.68015","0.00588"
"3378","20.23200","1.68612","0.00553"
"3390","20.30400","1.69216","0.00547"
"3402","20.37600","1.69814","0.00559"
"3414","20.44800","1.70418","0.00594"
"3426","20.52000","1.71010","0.00570"
"3438","20.59200","1.71614","0.00572"
"3450","20.66400","1.72212","0.00554"
"3462","20.73600","1.72816","0.00591"
"3474","20.80800","1.73408","0.00614"
"3486","20.88000","1.74017","0.00575"
"3498","20.95200","1.74615","0.00569"
"3510","21.02400","1.75219","0.00594"
"3522","21.09600","1.75811","0.00580"
"3534","21.16800","1.76415","0.00578"
"3546","21.24000","1.77013","0.00572"
"3558","21.31200","1.77617","0.00578"
"3570","21.38400","1.78209","0.00580"
"3582","21.45600","1.78819","0.00585"
"3594","21.52800","1.79410","0.00580"
"3606","21.60000","1.80014","0.00599"
"3618","21.67200","1.80606","0.00593"
"3630","21.74400","1.81216","0.00616"
"3642","21.81600","1.81820","0.00572"
"3654","21.88800","1.82424","0.00629"
"3666","21.96000","1.83016","0.00610"
"3678","22.03200","1.83614","0.00591"
"3690","22.10400","1.84212","0.00601"
"3702","22.17600","1.84815","0.00584"
"3714","22.24800","1.85413","0.00558"
"3726","22.32000","1.86017","0.00612"
"3738","22.39200","1.86615","0.00566"
"3750","22.46400","1.87219","0.00599"
"3762","22.53600","1.87817","0.00633"
"3774","22.60800","1.88421","0.00608"
"3786","22.68000","1.89013","0.00612"
"3798","22.75200","1.89617","0.00602"
"3810","22.82400","1.90214","0.00572"
"3822","22.89600","1.90818","0.00627"
"3834","22.96800","1.91416","0.00597"
"3846","23.04000","1.92020","0.00612"
"3858","23.11200","1.92618","0.00593"
"3870","23.18400","1.93210","0.00606"
"3882","23.25600","1.93808","0.00619"
"3894","23.32800","1.94412","0.00609"
"3906","23.40000","1.95016","0.00615"
"3918","23.47200","1.95619","0.00632"
"3930","23.54400","1.96211","0.00602"
"3942","23.61600","1.96809","0.00576"
"3954","23.68800","1.97413","0.00615"
"3966","23.76000","1.98011","0.00629"
"3978","23.83200","1.98609","0.00651"
"3990","23.90400","1.99213","0.00593"
"4002","23.97600","1.99817","0.00598"
"4014","24.04800","2.00420","0.00599"
"4026","24.12000","2.01024","0.00603"
"4038","24.19200","2.01616","0.00604"
"4050","24.26400","2.02214","0.00617"
"4062","24.33600","2.02812","0.00642"
"4074","24.40800","2.03416","0.00590"
"4086","24.48000","2.04020","0.00590"
"4098","24.55200","2.04618","0.00588"
"4110","24.62400","2.05216","0.00587"
"4122","24.69600","2.05819","0.00649"
"4134","24.76800","2.06417","0.00575"
"4146","24.84000","2.07009","0.00621"
"4158","24.91200","2.07607","0.00610"
"4170","24.98400","2.08211","0.00616"
"4182","25.05600","2.08821","0.00640"
"4194","25.12800","2.09419","0.00621"
"4206","25.20000","2.10017","0.00589"
"4218","25.27200","2.10615","0.00645"
"4230","25.34400","2.11213","0.00603"
"4242","25.41600","2.11810","0.00637"
"4254","25.48800","2.12408","0.00605"
"4266","25.56000","2.13012","0.00606"
"4278","25.63200","2.13616","0.00590"
"4290","25.70400","2.14214","0.00636"
"4302","25.77600","2.14812","0.00637"
"4314","25.84800","2.15410","0.00611"
"4326","25.92000","2.16014","0.00607"
"4338","25.99200","2.16606","0.00599"
"4350","26.06400","2.17209","0.00612"
"4362","26.13600","2.17813","0.00623"
"4374","26.20800","2.18417","0.00607"
"4386","26.28000","2.19015","0.00631"
"4398","26.35200","2.19613","0.00603"
"4410","26.42400","2.20217","0.00609"
"4422","26.49600","2.20815","0.00626"
"4434","26.56800","2.21413","0.00633"
"4446","26.64000","2.22016","0.00609"
"4458","26.71200","2.22620","0.00643"
"4470","26.78400","2.23218","0.00666"
"4482","26.85600","2.23816","0.00628"
"4494","26.92800","2.24414","0.00600"
"4506","27.00000","2.25012","0.00628"
"4518","27.07200","2.25616","0.00580"
"4530","27.14400","2.26214","0.00634"
"4542","27.21600","2.26818","0.00632"
"4554","27.28800","2.27421","0.00579"
"4566","27.36000","2.28019","0.00632"
"4578","27.43200","2.28611","0.00631"
"4590","27.50400","2.29215","0.00619"
"4602","27.57600","2.29807","0.00621"
"4614","27.64800","2.30411","0.00643"
"4626","27.72000","2.31015","0.00667"
"4638","27.79200","2.31619","0.00616"
"4650","27.86400","2.32217","0.00647"
"4662","27.93600","2.32820","0.00605"
"4674","28.00800","2.33412","0.00632"
"4686","28.08000","2.34010","0.00631"
"4698","28.15200","2.34608","0.00630"
"4710","28.22400","2.35212","0.00609"
"4722","28.29600","2.35816","0.00658"
"4734","28.36800","2.36414","0.00618"
"4746","28.44000","2.37018","0.00647"
"4758","28.51200","2.37616","0.00637"
"4770","28.58400","2.38219","0.00646"
"4782","28.65600","2.38811","0.00663"
"4794","28.72800","2.39415","0.00626"
"4806","28.80000","2.40013","0.00634"
"4818","28.87200","2.40617","0.00652"
"4830","28.94400","2.41215","0.00639"
"4842","29.01600","2.41819","0.00629"
"4854","29.08800","2.42417","0.00585"
"4866","29.16000","2.43015","0.00647"
"4878","29.23200","2.43612","0.00659"
"4890","29.30400","2.44216","0.00663"
"4902","29.37600","2.44820","0.00646"
"4914","29.44800","2.45418","0.00632"
"4926","29.52000","2.46016","0.00653"
"4938","29.59200","2.46620","0.00639"
"4950","29.66400","2.47218","0.00646"
"4962","29.73600","2.47816","0.00626"
"4974","29.80800","2.48414","0.00645"
"4986","29.88000","2.49017","0.00671"
"4998","29.95200","2.49615","0.00609"
"5010","30.02400","2.50219","0.00648"
"5022","30.09600","2.50817","0.00643"
"5034","30.16800","2.51415","0.00611"
"5046","30.24000","2.52013","0.00674"
"5058","30.31200","2.52611","0.00691"
"5070","30.38400","2.53215","0.00623"
"5082","30.45600","2.53819","0.00628"
"5094","30.52800","2.54416","0.00651"
"5106","30.60000","2.55020","0.00619"
"5118","30.67200","2.55612","0.00656"
"5130","30.74400","2.56216","0.00667"
"5142","30.81600","2.56814","0.00667"
"5154","30.88800","2.57418","0.00652"
"5166","30.96000","2.58016","0.00660"
"5178","31.03200","2.58620","0.00607"
"5190","31.10400","2.59218","0.00662"
"5202","31.17600","2.59821","0.00630"
"5214","31.24800","2.60413","0.00629"
"5226","31.32000","2.61011","0.00661"
"5238","31.39200","2.61615","0.00671"
"5250","31.46400","2.62219","0.00641"
"5262","31.53600","2.62817","0.00623"
"5274","31.60800","2.63415","0.00671"
"5286","31.68000","2.64019","0.00657"
"5298","31.75200","2.64616","0.00670"
"5310","31.82400","2.65214","0.00680"
"5322","31.89600","2.65806","0.00683"
"5334","31.96800","2.66416","0.00678"
"5346","32.04000","2.67014","0.00690"
"5358","32.11200","2.67618","0.00658"
"5370","32.18400","2.68216","0.00669"
"5382","32.25600","2.68814","0.00658"
"5394","32.32800","2.69412","0.00651"
"5406","32.40000","2.70010","0.00662"
"5418","32.47200","2.70613","0.00656"
"5430","32.54400","2.71211","0.00659"
"5442","32.61600","2.71821","0.00631"
"5454","32.68800","2.72413","0.00647"
"5466","32.76000","2.73017","0.00656"
"5478","32.83200","2.73609","0.00657"
"5490","32.90400","2.74213","0.00659"
"5502","32.97600","2.74805","0.00655"
"5514","33.04800","2.75414","0.00711"
"5526","33.12000","2.76018","0.00640"
"5538","33.19200","2.76622","0.00671"
"5550","33.26400","2.77214","0.00624"
"5562","33.33600","2.77818","0.00672"
"5574","33.40800","2.78410","0.00658"
"5586","33.48000","2.79014","0.00672"
"5598","33.55200","2.79606","0.00664"
"5610","33.62400","2.80216","0.00676"
"5622","33.69600","2.80819","0.00667"
"5634","33.76800","2.81423","0.00679"
"5646","33.84000","2.82015","0.00701"
"5658","33.91200","2.82619","0.00668"
"5670","33.98400","2.83211","0.00661"
"5682","34.05600","2.83815","0.00701"
"5694","34.12800","2.84407","0.00663"
"5706","34.20000","2.85017","0.00629"
"5718","34.27200","2.85615","0.00660"
"5730","34.34400","2.86218","0.00656"
"5742","34.41600","2.86810","0.00666"
"5754","34.48800","2.87414","0.00689"
"5766","34.56000","2.88012","0.00668"
"5778","34.63200","2.88616","0.00684"
"5790","34.70400","2.89214","0.00670"
"5802","34.77600","2.89818","0.00686"
"5814","34.84800","2.90416","0.00694"
"5826","34.92000","2.91020","0.00686"
"5838","34.99200","2.91612","0.00664"
"5850","35.06400","2.92215","0.00667"
"5862","35.13600","2.92807","0.00729"
"5874","35.20800","2.93417","0.00678"
"5886","35.28000","2.94021","0.00677"
"5898","35.35200","2.94619","0.00681"
"5910","35.42400","2.95223","0.00657"
"5922","35.49600","2.95821","0.00685"
"5934","35.56800","2.96419","0.00675"
"5946","35.64000","2.97016","0.00689"
"5958","35.71200","2.97614","0.00723"
"5970","35.78400","2.98218","0.00682"
"5982","35.85600","2.98816","0.00689"
"5994","35.92800","2.99420","0.00674"
"6006","36.00000","3.00018","0.00653"
"6018","36.07200","3.00622","0.00713"
"6030","36.14400","3.01214","0.00686"
"6042","36.21600","3.01818","0.00709"
"6054","36.28800","3.02410","0.00684"
"6066","36.36000","3.03019","0.00648"
"6078","36.43200","3.03611","0.00671"
"6090","36.50400","3.04221","0.00692"
"6102","36.57600","3.04813","0.00640"
"6114","36.64800","3.05417","0.00695"
"6126","36.72000","3.06009","0.00700"
"6138","36.79200","3.06619","0.00700"
"6150","36.86400","3.07217","0.00698"
"6162","36.93600","3.07820","0.00696"
"6174","37.00800","3.08418","0.00680"
"6186","37.08000","3.09022","0.00701"
"6198","37.15200","3.09620","0.00680"
"6210","37.22400","3.10218","0.00709"
"6222","37.29600","3.10810","0.00667"
"6234","37.36800","3.11420","0.00666"
"6246","37.44000","3.12018","0.00704"
"6258","37.51200","3.12622","0.00679"
"6270","37.58400","3.13213","0.00716"
"6282","37.65600","3.13817","0.00676"
"6294","37.72800","3.14415","0.00690"
"6306","37.80000","3.15019","0.00708"
"6318","37.87200","3.15611","0.00652"
"6330","37.94400","3.16215","0.00677"
"6342","38.01600","3.16813","0.00734"
"6354","38.08800","3.17417","0.00675"
"6366","38.16000","3.18015","0.00678"
"6378","38.23200","3.18618","0.00697"
"6390","38.30400","3.19210","0.00679"
"6402","38.37600","3.19814","0.00707"
"6414","38.44800","3.20412","0.00688"
"6426","38.52000","3.21022","0.00684"
"6438","38.59200","3.21614","0.00725"
"6450","38.66400","3.22212","0.00689"
"6462","38.73600","3.22810","0.00731"
"6474","38.80800","3.23414","0.00657"
"6486","38.88000","3.24011","0.00697"
"6498","38.95200","3.24609","0.00694"
"6510","39.02400","3.25213","0.00697"
"6522","39.09600","3.25817","0.00710"
"6534","39.16800","3.26421","0.00643"
"6546","39.24000","3.27013","0.00722"
"6558","39.31200","3.27617","0.00672"
"6570","39.38400","3.28209","0.00719"
"6582","39.45600","3.28813","0.00706"
"6594","39.52800","3.29410","0.00719"
"6606","39.60000","3.30020","0.00692"
"6618","39.67200","3.30618","0.00688"
"6630","39.74400","3.31222","0.00698"
"6642","39.81600","3.31814","0.00724"
"6654","39.88800","3.32412","0.00664"
"6666","39.96000","3.33010","0.00692"
"6678","40.03200","3.33614","0.00717"
"6690","40.10400","3.34218","0.00683"
"6702","40.17600","3.34815","0.00705"
"6714","40.24800","3.35425","0.00724"
"6726","40.32000","3.36017","0.00680"
"6738","40.39200","3.36621","0.00684"
"6750","40.46400","3.37207","0.00689"
"6762","40.53600","3.37817","0.00683"
"6774","40.60800","3.38415","0.00715"
"6786","40.68000","3.39025","0.00707"
"6798","40.75200","3.39617","0.00727"
"6810","40.82400","3.40214","0.00683"
"6822","40.89600","3.40812","0.00687"
"6834","40.96800","3.41416","0.00726"
"6846","41.04000","3.42008","0.00698"
"6858","41.11200","3.42618","0.00691"
"6870","41.18400","3.43216","0.00669"
"6882","41.25600","3.43820","0.00698"
"6894","41.32800","3.44418","0.00669"
"6906","41.40000","3.45021","0.00691"
"6918","41.47200","3.45613","0.00699"
"6930","41.54400","3.46211","0.00710"
"6942","41.61600","3.46809","0.00712"
"6954","41.68800","3.47419","0.00685"
"6966","41.76000","3.48017","0.00690"
"6978","41.83200","3.48621","0.00706"
"6990","41.90400","3.49219","0.00681"
"7002","41.97600","3.49817","0.00699"
"7014","42.04800","3.50415","0.00694"
"7026","42.12000","3.51012","0.00714"
"7038","42.19200","3.51610","0.00696"
"7050","42.26400","3.52220","0.00697"
"7062","42.33600","3.52818","0.00680"
"7074","42.40800","3.53422","0.00740"
"7086","42.48000","3.54014","0.00694"
"7098","42.55200","3.54618","0.00691"
"7110","42.62400","3.55210","0.00728"
"7122","42.69600","3.55819","0.00737"
"7134","42.76800","3.56411","0.00717"
"7146","42.84000","3.57015","0.00706"
"7158","42.91200","3.57613","0.00715"
"7170","42.98400","3.58217","0.00693"
"7182","43.05600","3.58815","0.00707"
"7194","43.12800","3.59413","0.00699"
"7206","43.20000","3.60011","0.00672"
"7218","43.27200","3.60615","0.00742"
"7230","43.34400","3.61213","0.00699"
"7242","43.41600","3.61816","0.00696"
"7254","43.48800","3.62414","0.00762"
"7266","43.56000","3.63018","0.00699"
"7278","43.63200","3.63610","0.00741"
"7290","43.70400","3.64214","0.00718"
"7302","43.77600","3.64812","0.00702"
"7314","43.84800","3.65416","0.00706"
"7326","43.92000","3.66020","0.00681"
"7338","43.99200","3.66617","0.00749"
"7350","44.06400","3.67215","0.00699"
"7362","44.13600","3.67813","0.00712"
"7374","44.20800","3.68411","0.00693"
"7386","44.28000","3.69009","0.00715"
"7398","44.35200","3.69613","0.00721"
"7410","44.42400","3.70217","0.00701"
"7422","44.49600","3.70815","0.00720"
"7434","44.56800","3.71419","0.00723"
"7446","44.64000","3.72016","0.00724"
"7458","44.71200","3.72614","0.00725"
"7470","44.78400","3.73212","0.00731"
"7482","44.85600","3.73816","0.00731"
"7494","44.92800","3.74414","0.00743"
"7506","45.00000","3.75018","0.00734"
"7518","45.07200","3.75616","0.00713"
"7530","45.14400","3.76220","0.00715"
"7542","45.21600","3.76818","0.00713"
"7554","45.28800","3.77415","0.00733"
"7566","45.36000","3.78007","0.00706"
"7578","45.43200","3.78611","0.00731"
"7590","45.50400","3.79215","0.00733"
"7602","45.57600","3.79813","0.00730"
"7614","45.64800","3.80411","0.00748"
"7626","45.72000","3.81015","0.00732"
"7638","45.79200","3.81613","0.00710"
"7650","45.86400","3.82211","0.00751"
"7662","45.93600","3.82808","0.00724"
"7674","46.00800","3.83412","0.00725"
"7686","46.08000","3.84016","0.00708"
"7698","46.15200","3.84614","0.00709"
"7710","46.22400","3.85212","0.00713"
"7722","46.29600","3.85810","0.00718"
"7734","46.36800","3.86414","0.00703"
"7746","46.44000","3.87012","0.00716"
"7758","46.51200","3.87616","0.00755"
"7770","46.58400","3.88213","0.00747"
"7782","46.65600","3.88817","0.00705"
"7794","46.72800","3.89415","0.00707"
"7806","46.80000","3.90013","0.00718"
"7818","46.87200","3.90611","0.00753"
"7830","46.94400","3.91215","0.00742"
"7842","47.01600","3.91813","0.00678"
"7854","47.08800","3.92417","0.00726"
"7866","47.16000","3.93015","0.00767"
"7878","47.23200","3.93612","0.00680"
"7890","47.30400","3.94216","0.00709"
"7902","47.37600","3.94814","0.00752"
"7914","47.44800","3.95412","0.00719"
"7926","47.52000","3.96010","0.00710"
"7938","47.59200","3.96614","0.00718"
"7950","47.66400","3.97218","0.00726"
"7962","47.73600","3.97816","0.00758"
"7974","47.80800","3.98414","0.00705"
"7986","47.88000","3.99011","0.00711"
"7998","47.95200","3.99609","0.00694"
"8010","48.02400","4.00213","0.00720"
"8022","48.09600","4.00811","0.00710"
"8034","48.16800","4.01415","0.00747"
"8046","48.24000","4.02019","0.00729"
"8058","48.31200","4.02617","0.00721"
"8070","48.38400","4.03215","0.00735"
"8082","48.45600","4.03819","0.00743"
"8094","48.52800","4.04410","0.00745"
"8106","48.60000","4.05014","0.00726"
"8118","48.67200","4.05618","0.00729"
"8130","48.74400","4.06216","0.00724"
"8142","48.81600","4.06814","0.00747"
"8154","48.88800","4.07418","0.00752"
"8166","48.96000","4.08016","0.00747"
"8178","49.03200","4.08614","0.00722"
"8190","49.10400","4.09211","0.00718"
"8202","49.17600","4.09815","0.00769"
"8214","49.24800","4.10419","0.00754"
"8226","49.32000","4.11017","0.00740"
"8238","49.39200","4.11621","0.00734"
"8250","49.46400","4.12213","0.00734"
"8262","49.53600","4.12811","0.00747"
"8274","49.60800","4.13415","0.00722"
"8286","49.68000","4.14013","0.00739"
"8298","49.75200","4.14611","0.00727"
"8310","49.82400","4.15214","0.00717"
"8322","49.89600","4.15818","0.00730"
"8334","49.96800","4.16422","0.00736"
"8346","50.04000","4.17014","0.00739"
"8358","50.11200","4.17612","0.00767"
"8370","50.18400","4.18210","0.00737"
"8382","50.25600","4.18820","0.00762"
"8394","50.32800","4.19418","0.00748"
"8406","50.40000","4.20021","0.00742"
"8418","50.47200","4.20619","0.00763"
"8430","50.54400","4.21217","0.00759"
"8442","50.61600","4.21815","0.00773"
"8454","50.68800","4.22413","0.00731"
"8466","50.76000","4.23005","0.00739"
"8478","50.83200","4.23621","0.00769"
"8490","50.90400","4.24225","0.00736"
"8502","50.97600","4.24817","0.00743"
"8514","51.04800","4.25414","0.00747"
"8526","51.12000","4.26018","0.00752"
"8538","51.19200","4.26616","0.00774"
"8550","51.26400","4.27214","0.00740"
"8562","51.33600","4.27812","0.00746"
"8574","51.40800","4.28416","0.00764"
"8586","51.48000","4.29014","0.00751"
"8598","51.55200","4.29618","0.00742"
"8610","51.62400","4.30216","0.00761"
"8622","51.69600","4.30819","0.00759"
"8634","51.76800","4.31411","0.00724"
"8646","51.84000","4.32015","0.00757"
"8658","51.91200","4.32613","0.00760"
"8670","51.98400","4.33217","0.00762"
"8682","52.05600","4.33815","0.00727"
"8694","52.12800","4.34425","0.00734"
"8706","52.20000","4.35017","0.00752"
"8718","52.27200","4.35615","0.00742"
"8730","52.34400","4.36212","0.00688"
"8742","52.41600","4.36816","0.00767"
"8754","52.48800","4.37414","0.00741"
"8766","52.56000","4.38018","0.00727"
"8778","52.63200","4.38622","0.00712"
"8790","52.70400","4.39220","0.00758"
"8802","52.77600","4.39818","0.00766"
"8814","52.84800","4.40416","0.00766"
"8826","52.92000","4.41014","0.00750"
"8838","52.99200","4.41617","0.00757"
"8850","53.06400","4.42215","0.00711"
"8862","53.13600","4.42819","0.00733"
"8874","53.20800","4.43417","0.00765"
"8886","53.28000","4.44015","0.00730"
"8898","53.35200","4.44613","0.00734"
"8910","53.42400","4.45211","0.00747"
"8922","53.49600","4.45809","0.00763"
"8934","53.56800","4.46413","0.00784"
"8946","53.64000","4.47010","0.00731"
"8958","53.71200","4.47614","0.00767"
"8970","53.78400","4.48212","0.00770"
"8982","53.85600","4.48816","0.00763"
"8994","53.92800","4.49408","0.00742"
"9006","54.00000","4.50018","0.00764"
"9018","54.07200","4.50616","0.00778"
"9030","54.14400","4.51220","0.00738"
"9042","54.21600","4.51812","0.00762"
"9054","54.28800","4.52415","0.00758"
"9066","54.36000","4.53013","0.00750"
"9078","54.43200","4.53617","0.00774"
"9090","54.50400","4.54209","0.00742"
"9102","54.57600","4.54813","0.00764"
"9114","54.64800","4.55417","0.00747"
"9126","54.72000","4.56015","0.00737"
"9138","54.79200","4.56619","0.00748"
"9150","54.86400","4.57217","0.00767"
"9162","54.93600","4.57820","0.00767"
"9174","55.00800","4.58412","0.00744"
"9186","55.08000","4.59016","0.00740"
"9198","55.15200","4.59614","0.00778"
"9210","55.22400","4.60218","0.00769"
"9222","55.29600","4.60816","0.00766"
"9234","55.36800","4.61420","0.00760"
"9246","55.44000","4.62018","0.00774"
"9258","55.51200","4.62616","0.00755"
"9270","55.58400","4.63213","0.00760"
"9282","55.65600","4.63811","0.00762"
"9294","55.72800","4.64421","0.00757"
"9306","55.80000","4.65013","0.00761"
"9318","55.87200","4.65617","0.00733"
"9330","55.94400","4.66215","0.00754"
"9342","56.01600","4.66813","0.00736"
"9354","56.08800","4.67405","0.00740"
"9366","56.16000","4.68015","0.00761"
"9378","56.23200","4.68618","0.00728"
"9390","56.30400","4.69216","0.00775"
"9402","56.37600","4.69814","0.00740"
"9414","56.44800","4.70412","0.00735"
"9426","56.52000","4.71016","0.00738"
"9438","56.59200","4.71614","0.00757"
"9450","56.66400","4.72212","0.00768"
"9462","56.73600","4.72816","0.00765"
"9474","56.80800","4.73414","0.00714"
"9486","56.88000","4.74017","0.00759"
"9498","56.95200","4.74615","0.00790"
"9510","57.02400","4.75219","0.00752"
"9522","57.09600","4.75811","0.00770"
"9534","57.16800","4.76409","0.00734"
"9546","57.24000","4.77007","0.00744"
"9558","57.31200","4.77623","0.00742"
"9570","57.38400","4.78215","0.00746"
"9582","57.45600","4.78819","0.00738"
"9594","57.52800","4.79416","0.00790"
"9606","57.60000","4.80020","0.00745"
"9618","57.67200","4.80612","0.00756"
"9630","57.74400","4.81216","0.00771"
"9642","57.81600","4.81814","0.00797"
"9654","57.88800","4.82424","0.00719"
"9666","57.96000","4.83016","0.00706"
"9678","58.03200","4.83620","0.00744"
"9690","58.10400","4.84211","0.00751"
"9702","58.17600","4.84815","0.00733"
"9714","58.24800","4.85407","0.00715"
"9726","58.32000","4.86011","0.00762"
"9738","58.39200","4.86615","0.00744"
"9750","58.46400","4.87219","0.00755"
"9762","58.53600","4.87817","0.00775"
"9774","58.60800","4.88421","0.00745"
"9786","58.68000","4.89013","0.00753"
"9798","58.75200","4.89611","0.00765"
"9810","58.82400","4.90214","0.00771"
"9822","58.89600","4.90818","0.00746"
"9834","58.96800","4.91416","0.00737"
"9846","59.04000","4.92020","0.00777"
"9858","59.11200","4.92618","0.00775"
"9870","59.18400","4.93222","0.00765"
"9882","59.25600","4.93814","0.00736"
"9894","59.32800","4.94412","0.00767"
"9906","59.40000","4.95010","0.00736"
"9918","59.47200","4.95619","0.00751"
"9930","59.54400","4.96217","0.00800"
"9942","59.61600","4.96821","0.00765"
"9954","59.68800","4.97413","0.00782"
"9966","59.76000","4.98017","0.00777"
"9978","59.83200","4.98615","0.00753"
"9990","59.90400","4.99213","0.00765"
"10002","59.97600","4.99817","0.00754"
"10014","60.04800","5.00414","0.00776"
"10026","60.12000","5.01018","0.00783"
"10038","60.19200","5.01616","0.00775"
"10050","60.26400","5.02214","0.00765"
"10062","60.33600","5.02812","0.00792"
"10074","60.40800","5.03410","0.00780"
"10086","60.48000","5.04014","0.00761"
"10098","60.55200","5.04618","0.00749"
"10110","60.62400","5.05216","0.00798"
"10122","60.69600","5.05819","0.00767"
"10134","60.76800","5.06417","0.00755"
"10146","60.84000","5.07015","0.00776"
"10158","60.91200","5.07619","0.00763"
"10170","60.98400","5.08211","0.00770"
"10182","61.05600","5.08815","0.00782"
"10194","61.12800","5.09413","0.00758"
"10206","61.20000","5.10023","0.00734"
"10218","61.27200","5.10615","0.00787"
"10230","61.34400","5.11218","0.00805"
"10242","61.41600","5.11816","0.00766"
"10254","61.48800","5.12414","0.00774"
"10266","61.56000","5.13006","0.00797"
"10278","61.63200","5.13616","0.00745"
"10290","61.70400","5.14214","0.00766"
"10302","61.77600","5.14824","0.00772"
"10314","61.84800","5.15410","0.00760"
"10326","61.92000","5.16014","0.00785"
"10338","61.99200","5.16605","0.00757"
"10350","62.06400","5.17215","0.00779"
"10362","62.13600","5.17813","0.00766"
"10374","62.20800","5.18423","0.00795"
"10386","62.28000","5.19015","0.00767"
"10398","62.35200","5.19619","0.00769"
"10410","62.42400","5.20217","0.00745"
"10422","62.49600","5.20815","0.00786"
"10434","62.56800","5.21413","0.00760"
"10446","62.64000","5.22016","0.00745"
"10458","62.71200","5.22614","0.00759"
"10470","62.78400","5.23218","0.00790"
"10482","62.85600","5.23816","0.00757"
"10494","62.92800","5.24420","0.00785"
"10506","63.00000","5.25018","0.00748"
"10518","63.07200","5.25616","0.00779"
"10530","63.14400","5.26208","0.00812"
"10542","63.21600","5.26818","0.00766"
"10554","63.28800","5.27415","0.00753"
"10566","63.36000","5.28019","0.00792"
"10578","63.43200","5.28611","0.00778"
"10590","63.50400","5.29215","0.00782"
"10602","63.57600","5.29813","0.00723"
"10614","63.64800","5.30411","0.00782"
"10626","63.72000","5.31015","0.00743"
"10638","63.79200","5.31613","0.00781"
"10650","63.86400","5.32211","0.00748"
"10662","63.93600","5.32814","0.00790"
"10674","64.00800","5.33412","0.00768"
"10686","64.08000","5.34010","0.00746"
"10698","64.15200","5.34608","0.00765"
"10710","64.22400","5.35212","0.00797"
"10722","64.29600","5.35816","0.00778"
"10734","64.36800","5.36420","0.00749"
"10746","64.44000","5.37012","0.00748"
"10758","64.51200","5.37616","0.00777"
"10770","64.58400","5.38213","0.00769"
"10782","64.65600","5.38811","0.00777"
"10794","64.72800","5.39409","0.00763"
"10806","64.80000","5.40019","0.00760"
"10818","64.87200","5.40617","0.00759"
"10830","64.94400","5.41215","0.00774"
"10842","65.01600","5.41813","0.00733"
"10854","65.08800","5.42411","0.00774"
"10866","65.16000","5.43009","0.00785"
"10878","65.23200","5.43612","0.00800"
"10890","65.30400","5.44210","0.00785"
"10902","65.37600","5.44808","0.00766"
"10914","65.44800","5.45412","0.00764"
"10926","65.52000","5.46016","0.00764"
"10938","65.59200","5.46614","0.00810"
"10950","65.66400","5.47218","0.00790"
"10962","65.73600","5.47810","0.00765"
"10974","65.80800","5.48414","0.00783"
"10986","65.88000","5.49017","0.00760"
"10998","65.95200","5.49621","0.00748"
"11010","66.02400","5.50213","0.00768"
"11022","66.09600","5.50817","0.00770"
"11034","66.16800","5.51415","0.00776"
"11046","66.24000","5.52007","0.00796"
"11058","66.31200","5.52605","0.00754"
"11070","66.38400","5.53215","0.00803"
"11082","66.45600","5.53818","0.00800"
"11094","66.52800","5.54422","0.00764"
"11106","66.60000","5.55014","0.00783"
"11118","66.67200","5.55612","0.00777"
"11130","66.74400","5.56210","0.00780"
"11142","66.81600","5.56814","0.00761"
"11154","66.88800","5.57406","0.00796"
"11166","66.96000","5.58016","0.00777"
"11178","67.03200","5.58614","0.00793"
"11190","67.10400","5.59212","0.00789"
"11202","67.17600","5.59815","0.00778"
"11214","67.24800","5.60419","0.00785"
"11226","67.32000","5.61011","0.00779"
"11238","67.39200","5.61609","0.00786"
"11250","67.46400","5.62213","0.00758"
"11262","67.53600","5.62817","0.00773"
"11274","67.60800","5.63421","0.00815"
"11286","67.68000","5.64019","0.00761"
"11298","67.75200","5.64616","0.00780"
"11310","67.82400","5.65214","0.00766"
"11322","67.89600","5.65812","0.00788"
"11334","67.96800","5.66410","0.00783"
"11346","68.04000","5.67014","0.00756"
"11358","68.11200","5.67618","0.00781"
"11370","68.18400","5.68216","0.00776"
"11382","68.25600","5.68820","0.00778"
"11394","68.32800","5.69418","0.00803"
"11406","68.40000","5.70015","0.00779"
"11418","68.47200","5.70613","0.00764"
"11430","68.54400","5.71211","0.00762"
"11442","68.61600","5.71815","0.00783"
"11454","68.68800","5.72419","0.00771"
"11466","68.76000","5.73017","0.00756"
"11478","68.83200","5.73615","0.00758"
"11490","68.90400","5.74213","0.00765"
"11502","68.97600","5.74811","0.00758"
"11514","69.04800","5.75409","0.00775"
"11526","69.12000","5.76012","0.00754"
"11538","69.19200","5.76616","0.00749"
"11550","69.26400","5.77214","0.00765"
"11562","69.33600","5.77818","0.00732"
"11574","69.40800","5.78416","0.00775"
"11586","69.48000","5.79014","0.00764"
"11598","69.55200","5.79606","0.00778"
"11610","69.62400","5.80216","0.00721"
"11622","69.69600","5.80819","0.00788"
"11634","69.76800","5.81417","0.00767"
"11646","69.84000","5.82015","0.00792"
"11658","69.91200","5.82619","0.00719"
"11670","69.98400","5.83211","0.00780"
"11682","70.05600","5.83815","0.00746"
"11694","70.12800","5.84413","0.00775"
"11706","70.20000","5.85017","0.00773"
"11718","70.27200","5.85621","0.00754"
"11730","70.34400","5.86218","0.00789"
"11742","70.41600","5.86816","0.00762"
"11754","70.48800","5.87420","0.00799"
"11766","70.56000","5.88018","0.00766"
"11778","70.63200","5.88610","0.00767"
"11790","70.70400","5.89214","0.00776"
"11802","70.77600","5.89818","0.00762"
"11814","70.84800","5.90416","0.00748"
"11826","70.92000","5.91020","0.00750"
"11838","70.99200","5.91617","0.00773"
"11850","71.06400","5.92209","0.00774"
"11862","71.13600","5.92807","0.00772"
"11874","71.20800","5.93411","0.00773"
"11886","71.28000","5.94015","0.00758"
"11898","71.35200","5.94619","0.00758"
"11910","71.42400","5.95217","0.00750"
"11922","71.49600","5.95815","0.00753"
"11934","71.56800","5.96413","0.00782"
"11946","71.64000","5.97016","0.00804"
"11958","71.71200","5.97614","0.00740"
"11970","71.78400","5.98212","0.00751"
"11982","71.85600","5.98816","0.00765"
"11994","71.92800","5.99420","0.00794"
"12006","72.00000","6.00018","0.00755"
"12018","72.07200","6.00616","0.00749"
"12030","72.14400","6.01214","0.00759"
"12042","72.21600","6.01817","0.00742"
"12054","72.28800","6.02409","0.00743"
"12066","72.36000","6.03019","0.00754"
"12078","72.43200","6.03617","0.00766"
"12090","72.50400","6.04221","0.00762"
"12102","72.57600","6.04813","0.00820"
"12114","72.64800","6.05417","0.00721"
"12126","72.72000","6.06015","0.00749"
"12138","72.79200","6.06613","0.00804"
"12150","72.86400","6.07211","0.00769"
"12162","72.93600","6.07820","0.00766"
"12174","73.00800","6.08418","0.00775"
"12186","73.08000","6.09016","0.00746"
"12198","73.15200","6.09614","0.00763"
"12210","73.22400","6.10218","0.00740"
"12222","73.29600","6.10816","0.00748"
"12234","73.36800","6.11414","0.00797"
"12246","73.44000","6.12012","0.00767"
"12258","73.51200","6.12621","0.00757"
"12270","73.58400","6.13213","0.00785"
"12282","73.65600","6.13817","0.00768"
"12294","73.72800","6.14409","0.00792"
"12306","73.80000","6.15019","0.00767"
"12318","73.87200","6.15611","0.00764"
"12330","73.94400","6.16221","0.00774"
"12342","74.01600","6.16813","0.00792"
"12354","74.08800","6.17423","0.00773"
"12366","74.16000","6.18014","0.00752"
"12378","74.23200","6.18618","0.00801"
"12390","74.30400","6.19210","0.00761"
"12402","74.37600","6.19814","0.00792"
"12414","74.44800","6.20412","0.00768"
"12426","74.52000","6.21022","0.00747"
"12438","74.59200","6.21620","0.00765"
"12450","74.66400","6.22218","0.00758"
"12462","74.73600","6.22816","0.00788"
"12474","74.80800","6.23419","0.00782"
"12486","74.88000","6.24011","0.00758"
"12498","74.95200","6.24609","0.00770"
"12510","75.02400","6.25213","0.00770"
"12522","75.09600","6.25817","0.00770"
"12534","75.16800","6.26421","0.00719"
"12546","75.24000","6.27019","0.00787"
"12558","75.31200","6.27617","0.00773"
"12570","75.38400","6.28215","0.00762"
"12582","75.45600","6.28812","0.00747"
"12594","75.52800","6.29410","0.00732"
"12606","75.60000","6.30020","0.00784"
"12618","75.67200","6.30618","0.00748"
"12630","75.74400","6.31216","0.00771"
"12642","75.81600","6.31820","0.00759"
"12654","75.88800","6.32418","0.00771"
"12666","75.96000","6.33010","0.00773"
"12678","76.03200","6.33608","0.00766"
"12690","76.10400","6.34217","0.00806"
"12702","76.17600","6.34815","0.00771"
"12714","76.24800","6.35419","0.00776"
"12726","76.32000","6.36017","0.00802"
"12738","76.39200","6.36621","0.00748"
"12750","76.46400","6.37213","0.00794"
"12762","76.53600","6.37811","0.00791"
"12774","76.60800","6.38409","0.00756"
"12786","76.68000","6.39019","0.00769"
"12798","76.75200","6.39616","0.00754"
"12810","76.82400","6.40220","0.00730"
"12822","76.89600","6.40818","0.00793"
"12834","76.96800","6.41416","0.00749"
"12846","77.04000","6.42014","0.00760"
"12858","77.11200","6.42612","0.00743"
"12870","77.18400","6.43210","0.00755"
"12882","77.25600","6.43820","0.00751"
"12894","77.32800","6.44412","0.00784"
"12906","77.40000","6.45015","0.00771"
"12918","77.47200","6.45613","0.00776"
"12930","77.54400","6.46217","0.00757"
"12942","77.61600","6.46809","0.00809"
"12954","77.68800","6.47419","0.00785"
"12966","77.76000","6.48011","0.00783"
"12978","77.83200","6.48621","0.00792"
"12990","77.90400","6.49213","0.00781"
"13002","77.97600","6.49823","0.00753"
"13014","78.04800","6.50415","0.00767"
"13026","78.12000","6.51012","0.00769"
"13038","78.19200","6.51610","0.00771"
"13050","78.26400","6.52220","0.00768"
"13062","78.33600","6.52818","0.00769"
"13074","78.40800","6.53422","0.00778"
"13086","78.48000","6.54020","0.00759"
"13098","78.55200","6.54624","0.00786"
"13110","78.62400","6.55216","0.00749"
"13122","78.69600","6.55813","0.00740"
"13134","78.76800","6.56411","0.00785"
"13146","78.84000","6.57015","0.00782"
"13158","78.91200","6.57613","0.00740"
"13170","78.98400","6.58217","0.00787"
"13182","79.05600","6.58815","0.00768"
"13194","79.12800","6.59419","0.00754"
"13206","79.20000","6.60011","0.00765"
"13218","79.27200","6.60615","0.00776"
"13230","79.34400","6.61212","0.00769"
"13242","79.41600","6.61816","0.00788"
"13254","79.48800","6.62408","0.00759"
"13266","79.56000","6.63018","0.00761"
"13278","79.63200","6.63616","0.00793"
"13290","79.70400","6.64214","0.00792"
"13302","79.77600","6.64806","0.00791"
"13314","79.84800","6.65416","0.00801"
"13326","79.92000","6.66014","0.00766"
"13338","79.99200","6.66623","0.00758"
"13350","80.06400","6.67215","0.00726"
"13362","80.13600","6.67819","0.00775"
"13374","80.20800","6.68411","0.00778"
"13386","80.28000","6.69015","0.00802"
"13398","80.35200","6.69607","0.00767"
"13410","80.42400","6.70217","0.00760"
"13422","80.49600","6.70821","0.00801"
"13434","80.56800","6.71413","0.00754"
"13446","80.64000","6.72016","0.00785"
"13458","80.71200","6.72614","0.00757"
"13470","80.78400","6.73218","0.00776"
"13482","80.85600","6.73816","0.00813"
"13494","80.92800","6.74414","0.00784"
"13506","81.00000","6.75018","0.00782"
"13518","81.07200","6.75622","0.00783"
"13530","81.14400","6.76220","0.00745"
"13542","81.21600","6.76818","0.00773"
"13554","81.28800","6.77415","0.00739"
"13566","81.36000","6.78013","0.00751"
"13578","81.43200","6.78611","0.00814"
"13590","81.50400","6.79215","0.00775"
"13602","81.57600","6.79825","0.00760"
"13614","81.64800","6.80417","0.00771"
"13626","81.72000","6.81015","0.00791"
"13638","81.79200","6.81613","0.00770"
"13650","81.86400","6.82217","0.00746"
"13662","81.93600","6.82808","0.00778"
"13674","82.00800","6.83412","0.00773"
"13686","82.08000","6.84016","0.00741"
"13698","82.15200","6.84620","0.00746"
"13710","82.22400","6.85212","0.00755"
"13722","82.29600","6.85816","0.00765"
"13734","82.36800","6.86408","0.00778"
"13746","82.44000","6.87018","0.00791"
"13758","82.51200","6.87610","0.00780"
"13770","82.58400","6.88213","0.00747"
"13782","82.65600","6.88817","0.00793"
"13794","82.72800","6.89415","0.00796"
"13806","82.80000","6.90019","0.00748"
"13818","82.87200","6.90611","0.00772"
"13830","82.94400","6.91215","0.00789"
"13842","83.01600","6.91813","0.00763"
"13854","83.08800","6.92417","0.00768"
"13866","83.16000","6.93015","0.00773"
"13878","83.23200","6.93618","0.00767"
"13890","83.30400","6.94216","0.00763"
"13902","83.37600","6.94814","0.00783"
"13914","83.44800","6.95412","0.00784"
"13926","83.52000","6.96010","0.00777"
"13938","83.59200","6.96614","0.00773"
"13950","83.66400","6.97218","0.00760"
"13962","83.73600","6.97822","0.00792"
"13974","83.80800","6.98420","0.00787"
"13986","83.88000","6.99017","0.00769"
"13998","83.95200","6.99609","0.00769"
"14010","84.02400","7.00213","0.00764"
"14022","84.09600","7.00805","0.00793"
"14034","84.16800","7.01415","0.00786"
"14046","84.24000","7.02019","0.00786"
"14058","84.31200","7.02617","0.00752"
"14070","84.38400","7.03215","0.00763"
"14082","84.45600","7.03818","0.00803"
"14094","84.52800","7.04410","0.00741"
"14106","84.60000","7.05014","0.00812"
"14118","84.67200","7.05612","0.00796"
"14130","84.74400","7.06216","0.00774"
"14142","84.81600","7.06814","0.00748"
"14154","84.88800","7.07418","0.00753"
"14166","84.96000","7.08016","0.00802"
"14178","85.03200","7.08614","0.00776"
"14190","85.10400","7.09205","0.00776"
"14202","85.17600","7.09809","0.00771"
"14214","85.24800","7.10413","0.00783"
"14226","85.32000","7.11023","0.00785"
"14238","85.39200","7.11615","0.00752"
"14250","85.46400","7.12219","0.00776"
"14262","85.53600","7.12811","0.00771"
"14274","85.60800","7.13415","0.00759"
"14286","85.68000","7.14013","0.00748"
"14298","85.75200","7.14616","0.00797"
"14310","85.82400","7.15214","0.00794"
"14322","85.89600","7.15818","0.00779"
"14334","85.96800","7.16416","0.00791"
"14346","86.04000","7.17014","0.00764"
"14358","86.11200","7.17612","0.00785"
"14370","86.18400","7.18210","0.00776"
"14382","86.25600","7.18808","0.00800"
"14394","86.32800","7.19412","0.00793"
"14406","86.40000","7.20015","0.00823"
"14418","86.47200","7.20619","0.00788"
"14430","86.54400","7.21217","0.00793"
"14442","86.61600","7.21821","0.00755"
"14454","86.68800","7.22413","0.00794"
"14466","86.76000","7.23011","0.00769"
"14478","86.83200","7.23609","0.00792"
"14490","86.90400","7.24213","0.00736"
"14502","86.97600","7.24817","0.00804"
"14514","87.04800","7.25415","0.00796"
"14526","87.12000","7.26018","0.00783"
"14538","87.19200","7.26616","0.00783"
"14550","87.26400","7.27214","0.00811"
"14562","87.33600","7.27812","0.00757"
"14574","87.40800","7.28410","0.00794"
"14586","87.48000","7.29014","0.00768"
"14598","87.55200","7.29618","0.00793"
"14610","87.62400","7.30222","0.00802"
"14622","87.69600","7.30814","0.00786"
"14634","87.76800","7.31411","0.00788"
"14646","87.84000","7.32015","0.00779"
"14658","87.91200","7.32613","0.00776"
"14670","87.98400","7.33217","0.00788"
"14682","88.05600","7.33815","0.00801"
"14694","88.12800","7.34419","0.00797"
"14706","88.20000","7.35017","0.00796"
"14718","88.27200","7.35615","0.00820"
"14730","88.34400","7.36212","0.00742"
"14742","88.41600","7.36810","0.00774"
"14754","88.48800","7.37414","0.00808"
"14766","88.56000","7.38018","0.00797"
"14778","88.63200","7.38616","0.00811"
"14790","88.70400","7.39220","0.00826"
"14802","88.77600","7.39818","0.00778"
"14814","88.84800","7.40416","0.00799"
"14826","88.92000","7.41014","0.00760"
"14838","88.99200","7.41611","0.00760"
"14850","89.06400","7.42215","0.00776"
"14862","89.13600","7.42813","0.00760"
"14874","89.20800","7.43417","0.00784"
"14886","89.28000","7.44015","0.00790"
"14898","89.35200","7.44613","0.00758"
"14910","89.42400","7.45211","0.00776"
"14922","89.49600","7.45809","0.00793"
"14934","89.56800","7.46413","0.00795"
"14946","89.64000","7.47016","0.00778"
"14958","89.71200","7.47614","0.00774"
"14970","89.78400","7.48218","0.00767"
"14982","89.85600","7.48816","0.00775"
"14994","89.92800","7.49414","0.00787"
"15006","90.00000","7.50012","0.00770"
"15008","90.01200","7.50114","0.00784"